#VRML_SIM R2025a utf8

EXTERNPROTO "https://raw.githubusercontent.com/cyberbotics/webots/R2025a/projects/objects/backgrounds/protos/TexturedBackground.proto"
EXTERNPROTO "https://raw.githubusercontent.com/cyberbotics/webots/R2025a/projects/objects/backgrounds/protos/TexturedBackgroundLight.proto"
EXTERNPROTO "https://raw.githubusercontent.com/cyberbotics/webots/R2025a/projects/objects/floors/protos/RectangleArena.proto"
EXTERNPROTO "https://raw.githubusercontent.com/cyberbotics/webots/R2025a/projects/appearances/protos/Grass.proto"
EXTERNPROTO "https://raw.githubusercontent.com/cyberbotics/webots/R2025a/projects/objects/chairs/protos/Chair.proto"
EXTERNPROTO "https://raw.githubusercontent.com/cyberbotics/webots/R2025a/projects/objects/street_furniture/protos/TrashBin.proto"
EXTERNPROTO "https://raw.githubusercontent.com/cyberbotics/webots/R2025a/projects/objects/fruits/protos/Apple.proto"
EXTERNPROTO "https://raw.githubusercontent.com/cyberbotics/webots/R2025a/projects/objects/fruits/protos/Orange.proto"
EXTERNPROTO "https://raw.githubusercontent.com/cyberbotics/webots/R2025a/projects/objects/kitchen/breakfast/protos/CerealBox.proto"
EXTERNPROTO "https://raw.githubusercontent.com/cyberbotics/webots/R2025a/projects/objects/kitchen/breakfast/protos/BiscuitBox.proto"
EXTERNPROTO "https://raw.githubusercontent.com/cyberbotics/webots/R2025a/projects/objects/drinks/protos/BeerBottle.proto"
EXTERNPROTO "https://raw.githubusercontent.com/cyberbotics/webots/R2025a/projects/objects/hospital/protos/MedicineBottle.proto"

WorldInfo {
  basicTimeStep 2
}
Viewpoint {
  orientation -0.1792033844595288 0.890801209338815 0.4175635908921599 0.8979363164753714
  position -8.827702310011647 -5.137704353430689 7.91315280604935
}
TexturedBackground {
}
TexturedBackgroundLight {
}
DEF Grq20V2d3X5 Robot {
  translation -3.44027 -3.99976 0.39631
  rotation 0.00013369199860469803 5.477069942837518e-05 0.9999999895633099 1.57071
  children [
    Shape {
      appearance DEF base_link_material PBRAppearance {
        baseColor 0.8 0.4 0
        roughness 1
        metalness 0
      }
      geometry DEF TRUCK Mesh {
        url [
          "../protos/meshes/TRUCK.STL"
        ]
      }
    }
    HingeJoint {
      jointParameters HingeJointParameters {
        position 2.632845807564315e-05
        anchor 0.2987 0.06 0
      }
      device [
        RotationalMotor {
          name "FL_hip_joint"
          maxVelocity 22
          minPosition -0.741764919444444
          maxPosition 0.741764919444444
          maxTorque 150
        }
        PositionSensor {
          name "FL_hip_joint_sensor"
        }
      ]
      endPoint Solid {
        translation 0.2987 0.06 0
        rotation 1 0 0 2.6328458546773495e-05
        children [
          Shape {
            appearance DEF FL_hip_material PBRAppearance {
              baseColor 1 0.4 0.4
              roughness 1
              metalness 0
            }
            geometry DEF FL_HIP Mesh {
              url [
                "../protos/meshes/FL_HIP.STL"
              ]
            }
          }
          HingeJoint {
            jointParameters HingeJointParameters {
              position 0.839999118342544
              axis 0 1 0
              anchor 0 0.1341 0
            }
            device [
              RotationalMotor {
                name "FL_thigh_joint"
                maxVelocity 22
                minPosition -1.22173
                maxPosition 3.8397
                maxTorque 150
              }
              PositionSensor {
                name "FL_thigh_joint_sensor"
              }
            ]
            endPoint Solid {
              translation 0 0.1341 0
              rotation 0 1 0 0.8399991183425439
              children [
                Shape {
                  appearance DEF FL_thigh_material PBRAppearance {
                    baseColor 1 1 0.4
                    roughness 1
                    metalness 0
                  }
                  geometry DEF FL_THIGH Mesh {
                    url [
                      "../protos/meshes/FL_THIGH.STL"
                    ]
                  }
                }
                HingeJoint {
                  jointParameters HingeJointParameters {
                    position -1.6100445581272262
                    axis 0 1 0
                    anchor 0 0 -0.26
                  }
                  device [
                    RotationalMotor {
                      name "FL_calf_joint"
                      maxVelocity 22
                      minPosition -2.77507346333333
                      maxPosition -0.541052058888889
                      maxTorque 150
                    }
                    PositionSensor {
                      name "FL_calf_joint_sensor"
                    }
                  ]
                  endPoint Solid {
                    translation 0 0 -0.26
                    rotation 0 -1 0 1.6100445581272262
                    children [
                      Shape {
                        appearance DEF FL_calf_material PBRAppearance {
                          baseColor 0.4 1 0.4
                          roughness 1
                          metalness 0
                        }
                        geometry DEF FL_CALF Mesh {
                          url [
                            "../protos/meshes/FL_CALF.STL"
                          ]
                        }
                      }
                      Solid {
                        translation 0 0 -0.26149
                        children [
                          Shape {
                            appearance DEF FL_foot_material PBRAppearance {
                              baseColor 0 0.5 1
                              roughness 1
                              metalness 0
                            }
                            geometry Sphere {
                              radius 0.026
                            }
                          }
                        ]
                        name "FL_foot"
                        boundingObject Sphere {
                          radius 0.026
                        }
                        physics Physics {
                          density -1
                          mass 0.000205
                          centerOfMass [
                            0 0 0
                          ]
                          inertiaMatrix [
                            1.096001e-09 1.096001e-09 1.096001e-09
                            0 0 0
                          ]
                        }
                      }
                    ]
                    name "FL_calf"
                    boundingObject Group {
                      children [
                        Pose {
                          translation 0.00919 0 -0.06536
                          rotation 0 -1 0 0.139626
                          children [
                            Box {
                              size 0.033 0.033 0.23
                            }
                          ]
                        }
                        Pose {
                          translation 0.01381 0 -0.21574
                          rotation 0 1 0 0.24103
                          children [
                            Box {
                              size 0.036 0.036 0.09273
                            }
                          ]
                        }
                      ]
                    }
                    physics Physics {
                      density -1
                      mass 0.302786
                      centerOfMass [
                        0.008 0.003625 -0.128915
                      ]
                      inertiaMatrix [
                        0.0085187 0.0085725 0.0001128
                        8.6e-06 0.0003718 0.0001434
                      ]
                    }
                  }
                }
              ]
              name "FL_thigh"
              boundingObject Group {
                children [
                  Pose {
                    translation 0 -0.02125 0
                    rotation 0.5775032287046065 0.5775032287046065 -0.5770442285228318 2.093475
                    children [
                      Cylinder {
                        height 0.085
                        radius 0.058
                      }
                    ]
                  }
                  Pose {
                    translation -0.02158 0 -0.09691
                    rotation 0 1 0 0.122173
                    children [
                      Box {
                        size 0.06368 0.036 0.19764
                      }
                    ]
                  }
                  Pose {
                    translation -0.01645 0 -0.23181
                    rotation 0 -1 0 0.436332
                    children [
                      Box {
                        size 0.054 0.036 0.115
                      }
                    ]
                  }
                ]
              }
              physics Physics {
                density -1
                mass 2.930464
                centerOfMass [
                  -0.003481 -0.032125 -0.031894
                ]
                inertiaMatrix [
                  0.0264127 0.0232267 0.0081071
                  5.18e-05 0.0012845 0.0002853
                ]
              }
            }
          }
        ]
        name "FL_hip"
        physics Physics {
          density -1
          mass 1.87369
          centerOfMass [
            -0.002155 0.006319 1e-06
          ]
          inertiaMatrix [
            0.0021359 0.0034595 0.002322
            2.5e-05 0 0
          ]
        }
      }
    }
    HingeJoint {
      jointParameters HingeJointParameters {
        position 2.3550496206812056e-05
        anchor -0.2987 0.06 0
      }
      device [
        RotationalMotor {
          name "RL_hip_joint"
          maxVelocity 22
          minPosition -0.741764919444444
          maxPosition 0.741764919444444
          maxTorque 150
        }
        PositionSensor {
          name "RL_hip_joint_sensor"
        }
      ]
      endPoint Solid {
        translation -0.2987 0.06 0
        rotation 1 0 0 2.3550492112128164e-05
        children [
          Shape {
            appearance DEF RL_hip_material PBRAppearance {
              baseColor 0.8 1 0.8
              roughness 1
              metalness 0
            }
            geometry DEF RL_HIP Mesh {
              url [
                "../protos/meshes/RL_HIP.STL"
              ]
            }
          }
          HingeJoint {
            jointParameters HingeJointParameters {
              position 0.8400016141837824
              axis 0 1 0
              anchor 0 0.1341 0
            }
            device [
              RotationalMotor {
                name "RL_thigh_joint"
                maxVelocity 22
                minPosition -1.22173
                maxPosition 3.8397
                maxTorque 150
              }
              PositionSensor {
                name "RL_thigh_joint_sensor"
              }
            ]
            endPoint Solid {
              translation 0 0.1341 0
              rotation 0 1 0 0.8400016141837823
              children [
                Shape {
                  appearance DEF RL_thigh_material PBRAppearance {
                    baseColor 1 0.5 1
                    roughness 1
                    metalness 0
                  }
                  geometry USE FL_THIGH
                }
                HingeJoint {
                  jointParameters HingeJointParameters {
                    position -1.6100408994710087
                    axis 0 1 0
                    anchor 0 0 -0.26
                  }
                  device [
                    RotationalMotor {
                      name "RL_calf_joint"
                      maxVelocity 22
                      minPosition -2.77507346333333
                      maxPosition -0.541052058888889
                      maxTorque 150
                    }
                    PositionSensor {
                      name "RL_calf_joint_sensor"
                    }
                  ]
                  endPoint Solid {
                    translation 0 0 -0.26
                    rotation 0 -1 0 1.610040899471009
                    children [
                      Shape {
                        appearance DEF RL_calf_material PBRAppearance {
                          baseColor 1 0.4 0.4
                          roughness 1
                          metalness 0
                        }
                        geometry USE FL_CALF
                      }
                      Solid {
                        translation 0 0 -0.26149
                        children [
                          Shape {
                            appearance DEF RL_foot_material PBRAppearance {
                              baseColor 1 1 0.4
                              roughness 1
                              metalness 0
                            }
                            geometry Sphere {
                              radius 0.026
                            }
                          }
                        ]
                        name "RL_foot"
                        boundingObject Sphere {
                          radius 0.026
                        }
                        physics Physics {
                          density -1
                          mass 0.000205
                          centerOfMass [
                            0 0 0
                          ]
                          inertiaMatrix [
                            1.096001e-09 1.096001e-09 1.096001e-09
                            0 0 0
                          ]
                        }
                      }
                    ]
                    name "RL_calf"
                    boundingObject Group {
                      children [
                        Pose {
                          translation 0.00919 0 -0.06536
                          rotation 0 -1 0 0.139626
                          children [
                            Box {
                              size 0.033 0.033 0.23
                            }
                          ]
                        }
                        Pose {
                          translation 0.01381 0 -0.21574
                          rotation 0 1 0 0.24103
                          children [
                            Box {
                              size 0.036 0.036 0.09273
                            }
                          ]
                        }
                      ]
                    }
                    physics Physics {
                      density -1
                      mass 0.302786
                      centerOfMass [
                        0.008 0.003625 -0.128915
                      ]
                      inertiaMatrix [
                        0.0085187 0.0085725 0.0001128
                        8.6e-06 0.0003718 0.0001434
                      ]
                    }
                  }
                }
              ]
              name "RL_thigh"
              boundingObject Group {
                children [
                  Pose {
                    translation 0 -0.02125 0
                    rotation 0.5775032287046065 0.5775032287046065 -0.5770442285228318 2.093475
                    children [
                      Cylinder {
                        height 0.085
                        radius 0.058
                      }
                    ]
                  }
                  Pose {
                    translation -0.02158 0 -0.09691
                    rotation 0 1 0 0.122173
                    children [
                      Box {
                        size 0.06368 0.036 0.19764
                      }
                    ]
                  }
                  Pose {
                    translation -0.01645 0 -0.23181
                    rotation 0 -1 0 0.436332
                    children [
                      Box {
                        size 0.054 0.036 0.115
                      }
                    ]
                  }
                ]
              }
              physics Physics {
                density -1
                mass 2.930464
                centerOfMass [
                  -0.003481 -0.032125 -0.031894
                ]
                inertiaMatrix [
                  0.0264127 0.0232267 0.0081071
                  5.18e-05 0.0012845 0.0002853
                ]
              }
            }
          }
        ]
        name "RL_hip"
        physics Physics {
          density -1
          mass 1.87369
          centerOfMass [
            -0.002155 0.006319 1e-06
          ]
          inertiaMatrix [
            0.0021359 0.0034595 0.002322
            2.5e-05 0 0
          ]
        }
      }
    }
    HingeJoint {
      jointParameters HingeJointParameters {
        position -2.723636747514746e-05
        anchor 0.2987 -0.06 0
      }
      device [
        RotationalMotor {
          name "FR_hip_joint"
          maxVelocity 22
          minPosition -0.741764919444444
          maxPosition 0.741764919444444
          maxTorque 150
        }
        PositionSensor {
          name "FR_hip_joint_sensor"
        }
      ]
      endPoint Solid {
        translation 0.2987 -0.06 0
        rotation -0.9999999999999999 0 0 2.7236371616302063e-05
        children [
          Transform {
            scale 1 -1 1
            children [
              Shape {
                appearance DEF FR_hip_material PBRAppearance {
                  baseColor 1 0.4 0.4
                  roughness 1
                  metalness 0
                }
                geometry DEF FL_HIP_cw Mesh {
                  url [
                    "../protos/meshes/FL_HIP.STL"
                  ]
                  ccw FALSE
                }
              }
            ]
          }
          HingeJoint {
            jointParameters HingeJointParameters {
              position 0.8400017037363011
              axis 0 1 0
              anchor 0 -0.1341 0
            }
            device [
              RotationalMotor {
                name "FR_thigh_joint"
                maxVelocity 22
                minPosition -1.22173
                maxPosition 3.8397
                maxTorque 150
              }
              PositionSensor {
                name "FR_thigh_joint_sensor"
              }
            ]
            endPoint Solid {
              translation 0 -0.1341 0
              rotation 0 1 0 0.8400017037363012
              children [
                Transform {
                  scale 1 -1 1
                  children [
                    Shape {
                      appearance DEF FR_thigh_material PBRAppearance {
                        baseColor 1 1 0.4
                        roughness 1
                        metalness 0
                      }
                      geometry DEF FL_THIGH_cw Mesh {
                        url [
                          "../protos/meshes/FL_THIGH.STL"
                        ]
                        ccw FALSE
                      }
                    }
                  ]
                }
                HingeJoint {
                  jointParameters HingeJointParameters {
                    position -1.6100458252532375
                    axis 0 1 0
                    anchor 0 0 -0.26
                  }
                  device [
                    RotationalMotor {
                      name "FR_calf_joint"
                      maxVelocity 22
                      minPosition -2.77507346333333
                      maxPosition -0.541052058888889
                      maxTorque 150
                    }
                    PositionSensor {
                      name "FR_calf_joint_sensor"
                    }
                  ]
                  endPoint Solid {
                    translation 0 0 -0.26
                    rotation 0 -1 0 1.6100458252532375
                    children [
                      Transform {
                        scale 1 -1 1
                        children [
                          Shape {
                            appearance DEF FR_calf_material PBRAppearance {
                              baseColor 0.4 1 0.4
                              roughness 1
                              metalness 0
                            }
                            geometry DEF FL_CALF_cw Mesh {
                              url [
                                "../protos/meshes/FL_CALF.STL"
                              ]
                              ccw FALSE
                            }
                          }
                        ]
                      }
                      Solid {
                        translation 0 0 -0.26149
                        children [
                          Shape {
                            appearance DEF FR_foot_material PBRAppearance {
                              baseColor 0 0.5 1
                              roughness 1
                              metalness 0
                            }
                            geometry Sphere {
                              radius 0.026
                            }
                          }
                        ]
                        name "FR_foot"
                        boundingObject Sphere {
                          radius 0.026
                        }
                        physics Physics {
                          density -1
                          mass 0.000205
                          centerOfMass [
                            0 0 0
                          ]
                          inertiaMatrix [
                            1.096001e-09 1.096001e-09 1.096001e-09
                            0 0 0
                          ]
                        }
                      }
                    ]
                    name "FR_calf"
                    boundingObject Group {
                      children [
                        Pose {
                          translation 0.00919 0 -0.06536
                          rotation 0 -1 0 0.139626
                          children [
                            Box {
                              size 0.033 0.033 0.23
                            }
                          ]
                        }
                        Pose {
                          translation 0.01381 0 -0.21574
                          rotation 0 1 0 0.24103
                          children [
                            Box {
                              size 0.036 0.036 0.09273
                            }
                          ]
                        }
                      ]
                    }
                    physics Physics {
                      density -1
                      mass 0.302786
                      centerOfMass [
                        0.008 -0.003625 -0.128915
                      ]
                      inertiaMatrix [
                        0.0085187 0.0085725 0.0001128
                        -8.6e-06 0.0003718 -0.0001434
                      ]
                    }
                  }
                }
              ]
              name "FR_thigh"
              boundingObject Group {
                children [
                  Pose {
                    translation 0 0.02125 0
                    rotation 0.5775032287046065 0.5775032287046065 -0.5770442285228318 2.093475
                    children [
                      Cylinder {
                        height 0.085
                        radius 0.058
                      }
                    ]
                  }
                  Pose {
                    translation -0.02158 0 -0.09691
                    rotation 0 1 0 0.122173
                    children [
                      Box {
                        size 0.06368 0.036 0.19764
                      }
                    ]
                  }
                  Pose {
                    translation -0.01645 0 -0.23181
                    rotation 0 -1 0 0.436332
                    children [
                      Box {
                        size 0.054 0.036 0.115
                      }
                    ]
                  }
                ]
              }
              physics Physics {
                density -1
                mass 2.930464
                centerOfMass [
                  -0.003481 0.032125 -0.031894
                ]
                inertiaMatrix [
                  0.0264127 0.0232267 0.0081071
                  -5.18e-05 0.0012845 -0.0002853
                ]
              }
            }
          }
        ]
        name "FR_hip"
        physics Physics {
          density -1
          mass 1.87369
          centerOfMass [
            -0.002155 -0.006319 1e-06
          ]
          inertiaMatrix [
            0.0021359 0.0034595 0.002322
            -2.5e-05 0 0
          ]
        }
      }
    }
    HingeJoint {
      jointParameters HingeJointParameters {
        position -2.4165622630865946e-05
        anchor -0.2987 -0.06 0
      }
      device [
        RotationalMotor {
          name "RR_hip_joint"
          maxVelocity 22
          minPosition -0.741764919444444
          maxPosition 0.741764919444444
          maxTorque 150
        }
        PositionSensor {
          name "RR_hip_joint_sensor"
        }
      ]
      endPoint Solid {
        translation -0.2987 -0.06 0
        rotation -0.9999999999999999 0 0 2.4165622503050426e-05
        children [
          Transform {
            scale 1 -1 1
            children [
              Shape {
                appearance DEF RR_hip_material PBRAppearance {
                  baseColor 0.8 1 0.8
                  roughness 1
                  metalness 0
                }
                geometry DEF RL_HIP_cw Mesh {
                  url [
                    "../protos/meshes/RL_HIP.STL"
                  ]
                  ccw FALSE
                }
              }
            ]
          }
          HingeJoint {
            jointParameters HingeJointParameters {
              position 0.84000168515963
              axis 0 1 0
              anchor 0 -0.1341 0
            }
            device [
              RotationalMotor {
                name "RR_thigh_joint"
                maxVelocity 22
                minPosition -1.22173
                maxPosition 3.8397
                maxTorque 150
              }
              PositionSensor {
                name "RR_thigh_joint_sensor"
              }
            ]
            endPoint Solid {
              translation 0 -0.1341 0
              rotation 0 1 0 0.8400016851596298
              children [
                Transform {
                  scale 1 -1 1
                  children [
                    Shape {
                      appearance DEF RR_thigh_material PBRAppearance {
                        baseColor 1 0.5 1
                        roughness 1
                        metalness 0
                      }
                      geometry USE FL_THIGH_cw
                    }
                  ]
                }
                HingeJoint {
                  jointParameters HingeJointParameters {
                    position -1.6100417356183143
                    axis 0 1 0
                    anchor 0 0 -0.26
                  }
                  device [
                    RotationalMotor {
                      name "RR_calf_joint"
                      maxVelocity 22
                      minPosition -2.77507346333333
                      maxPosition -0.541052058888889
                      maxTorque 150
                    }
                    PositionSensor {
                      name "RR_calf_joint_sensor"
                    }
                  ]
                  endPoint Solid {
                    translation 0 0 -0.26
                    rotation 0 -0.9999999999999999 0 1.6100417356183143
                    children [
                      Transform {
                        scale 1 -1 1
                        children [
                          Shape {
                            appearance DEF RR_calf_material PBRAppearance {
                              baseColor 1 0.4 0.4
                              roughness 1
                              metalness 0
                            }
                            geometry USE FL_CALF_cw
                          }
                        ]
                      }
                      Solid {
                        translation 0 0 -0.26149
                        children [
                          Shape {
                            appearance DEF RR_foot_material PBRAppearance {
                              baseColor 1 1 0.4
                              roughness 1
                              metalness 0
                            }
                            geometry Sphere {
                              radius 0.026
                            }
                          }
                        ]
                        name "RR_foot"
                        boundingObject Sphere {
                          radius 0.026
                        }
                        physics Physics {
                          density -1
                          mass 0.000205
                          centerOfMass [
                            0 0 0
                          ]
                          inertiaMatrix [
                            1.096001e-09 1.096001e-09 1.096001e-09
                            0 0 0
                          ]
                        }
                      }
                    ]
                    name "RR_calf"
                    boundingObject Group {
                      children [
                        Pose {
                          translation 0.00919 0 -0.06536
                          rotation 0 -1 0 0.139626
                          children [
                            Box {
                              size 0.033 0.033 0.23
                            }
                          ]
                        }
                        Pose {
                          translation 0.01381 0 -0.21574
                          rotation 0 1 0 0.24103
                          children [
                            Box {
                              size 0.036 0.036 0.09273
                            }
                          ]
                        }
                      ]
                    }
                    physics Physics {
                      density -1
                      mass 0.302786
                      centerOfMass [
                        0.008 -0.003625 -0.128915
                      ]
                      inertiaMatrix [
                        0.0085187 0.0085725 0.0001128
                        -8.6e-06 0.0003718 -0.0001434
                      ]
                    }
                  }
                }
              ]
              name "RR_thigh"
              boundingObject Group {
                children [
                  Pose {
                    translation 0 0.02125 0
                    rotation 0.5775032287046065 0.5775032287046065 -0.5770442285228318 2.093475
                    children [
                      Cylinder {
                        height 0.085
                        radius 0.058
                      }
                    ]
                  }
                  Pose {
                    translation -0.02158 0 -0.09691
                    rotation 0 1 0 0.122173
                    children [
                      Box {
                        size 0.06368 0.036 0.19764
                      }
                    ]
                  }
                  Pose {
                    translation -0.01645 0 -0.23181
                    rotation 0 -1 0 0.436332
                    children [
                      Box {
                        size 0.054 0.036 0.115
                      }
                    ]
                  }
                ]
              }
              physics Physics {
                density -1
                mass 2.930464
                centerOfMass [
                  -0.003481 0.032125 -0.031894
                ]
                inertiaMatrix [
                  0.0264127 0.0232267 0.0081071
                  -5.18e-05 0.0012845 -0.0002853
                ]
              }
            }
          }
        ]
        name "RR_hip"
        physics Physics {
          density -1
          mass 1.87369
          centerOfMass [
            -0.002155 -0.006319 1e-06
          ]
          inertiaMatrix [
            0.0021359 0.0034595 0.002322
            -2.5e-05 0 0
          ]
        }
      }
    }
    Solid {
      translation 0.17 0 0.08
      children [
        Shape {
          appearance DEF link0_material PBRAppearance {
            baseColor 0.75294 0.75294 0.75294
            roughness 1
            metalness 0
          }
          geometry DEF link0 Mesh {
            url [
              "../protos/meshes/link0.STL"
            ]
          }
        }
        HingeJoint {
          jointParameters HingeJointParameters {
            position 2.4393837900579164e-07
            axis 0 0 1
            anchor 0 0 0.0605
          }
          device [
            RotationalMotor {
              name "joint1"
              maxVelocity 1000
              minPosition -3.14
              maxPosition 2.6
              maxTorque 100
            }
            PositionSensor {
              name "joint1_sensor"
            }
          ]
          endPoint Solid {
            translation 2.89512306179239e-07 -2.18397648126588e-09 0.048155667943072245
            rotation -0.012598951169210755 -0.9999205996272115 -0.0002467196663010881 8.170833220990815e-05
            children [
              Shape {
                appearance DEF link1_material PBRAppearance {
                  baseColor 0.79216 0.81961 0.93333
                  roughness 1
                  metalness 0
                }
                geometry DEF link1 Mesh {
                  url [
                    "../protos/meshes/link1.STL"
                  ]
                }
              }
              HingeJoint {
                jointParameters HingeJointParameters {
                  position -1.491813345578169e-06
                  axis 0 1 0
                  anchor 0.02 0 0.04
                }
                device [
                  RotationalMotor {
                    name "joint2"
                    maxVelocity 1000
                    minPosition -0.1
                    maxPosition 3.6
                    maxTorque 100
                  }
                  PositionSensor {
                    name "joint2_sensor"
                  }
                ]
                endPoint Solid {
                  translation 0.02 0 0.04
                  rotation 0 -0.9999999999999999 0 1.4919031871299883e-06
                  children [
                    Shape {
                      appearance DEF link2_material PBRAppearance {
                        baseColor 0.75294 0.75294 0.75294
                        roughness 1
                        metalness 0
                      }
                      geometry DEF link2 Mesh {
                        url [
                          "../protos/meshes/link2.STL"
                        ]
                      }
                    }
                    HingeJoint {
                      jointParameters HingeJointParameters {
                        position -1.098660149878583e-05
                        axis 0 -1 -7e-06
                        anchor -0.264 0 0
                      }
                      device [
                        RotationalMotor {
                          name "joint3"
                          maxVelocity 1000
                          minPosition -1.098660149878583e-05
                          maxPosition 3.14
                          maxTorque 100
                        }
                        PositionSensor {
                          name "joint3_sensor"
                        }
                      ]
                      endPoint Solid {
                        translation -0.264 0 0
                        rotation 0.999999999984912 1.8275066785876427e-11 -5.49330074936543e-06 3.1416
                        children [
                          Shape {
                            appearance DEF link3_material PBRAppearance {
                              baseColor 1 0.98431 0.96471
                              roughness 1
                              metalness 0
                            }
                            geometry DEF link3 Mesh {
                              url [
                                "../protos/meshes/link3.STL"
                              ]
                            }
                          }
                          HingeJoint {
                            jointParameters HingeJointParameters {
                              position -2.644221717140738e-06
                              axis 0 1 0
                              anchor 0.245 0 -0.056
                            }
                            device [
                              RotationalMotor {
                                name "joint4"
                                maxVelocity 1000
                                minPosition -1.3
                                maxPosition 1.3
                                maxTorque 100
                              }
                              PositionSensor {
                                name "joint4_sensor"
                              }
                            ]
                            endPoint Solid {
                              translation 0.245 0 -0.056
                              rotation 0 -1 0 2.6441899553323326e-06
                              children [
                                Shape {
                                  appearance DEF link4_material PBRAppearance {
                                    baseColor 0.79216 0.81961 0.92941
                                    roughness 1
                                    metalness 0
                                  }
                                  geometry DEF link4 Mesh {
                                    url [
                                      "../protos/meshes/link4.STL"
                                    ]
                                  }
                                }
                                HingeJoint {
                                  jointParameters HingeJointParameters {
                                    position 8.155045084720863e-07
                                    axis 0 0 1
                                    anchor 0.06775 0.0005 -0.0865
                                  }
                                  device [
                                    RotationalMotor {
                                      name "joint5"
                                      maxVelocity 1000
                                      minPosition -1.57
                                      maxPosition 1.57
                                      maxTorque 100
                                    }
                                    PositionSensor {
                                      name "joint5_sensor"
                                    }
                                  ]
                                  endPoint Solid {
                                    translation 0.06775 0.0005 -0.0865
                                    rotation 0 0 1 8.15625916922337e-07
                                    children [
                                      Shape {
                                        appearance DEF link5_material PBRAppearance {
                                          baseColor 0.69804 0.69804 0.69804
                                          roughness 1
                                          metalness 0
                                        }
                                        geometry DEF link5 Mesh {
                                          url [
                                            "../protos/meshes/link5.STL"
                                          ]
                                        }
                                      }
                                      HingeJoint {
                                        jointParameters HingeJointParameters {
                                          position 4.419401312375422e-07
                                          anchor 0.02895 0 0.0865
                                        }
                                        device [
                                          RotationalMotor {
                                            name "joint6"
                                            maxVelocity 1000
                                            minPosition -2.1
                                            maxPosition 2.1
                                            maxTorque 100
                                          }
                                          PositionSensor {
                                            name "joint6_sensor"
                                          }
                                        ]
                                        endPoint Solid {
                                          translation 0.02895 0 0.0865
                                          rotation -1 0 0 3.141599558059869
                                          children [
                                            Shape {
                                              appearance DEF link6_material PBRAppearance {
                                                baseColor 0.89804 0.91765 0.92941
                                                roughness 1
                                                metalness 0
                                              }
                                              geometry DEF link6 Mesh {
                                                url [
                                                  "../protos/meshes/link6.STL"
                                                ]
                                              }
                                            }
                                            SliderJoint {
                                              jointParameters JointParameters {
                                                position -5.050564692333658e-10
                                                axis 0 1 0
                                              }
                                              device [
                                                LinearMotor {
                                                  name "joint7"
                                                  maxVelocity 1000
                                                  minPosition -5.050564692333658e-10
                                                  maxPosition 0.044
                                                  maxForce 100
                                                }
                                                PositionSensor {
                                                  name "joint7_sensor"
                                                }
                                              ]
                                              endPoint Solid {
                                                translation 0.08657 0.024895999494943533 -0.000244
                                                children [
                                                  Shape {
                                                    appearance DEF link7_material PBRAppearance {
                                                      roughness 1
                                                      metalness 0
                                                    }
                                                    geometry DEF link7 Mesh {
                                                      url [
                                                        "../protos/meshes/link7.STL"
                                                      ]
                                                    }
                                                  }
                                                ]
                                                name "link7"
                                                boundingObject Group {
                                                  children [
                                                    Pose {
                                                      translation 0.05 -0.023 0
                                                      children [
                                                        Box {
                                                          size 0.04 0.004 0.0105
                                                        }
                                                      ]
                                                    }
                                                    Pose {
                                                      translation 0.015 -0.023 0
                                                      children [
                                                        Box {
                                                          size 0.03 0.004 0.036
                                                        }
                                                      ]
                                                    }
                                                  ]
                                                }
                                                physics Physics {
                                                  density -1
                                                  mass 0.064798
                                                  centerOfMass [
                                                    -0.000355 -0.007827 -0.002988
                                                  ]
                                                  inertiaMatrix [
                                                    2e-05 3e-05 3e-05
                                                    0 0 0
                                                  ]
                                                }
                                              }
                                            }
                                            SliderJoint {
                                              jointParameters JointParameters {
                                                position 5.051413120144115e-10
                                                axis 0 -1 0
                                              }
                                              device [
                                                LinearMotor {
                                                  name "joint8"
                                                  maxVelocity 1000
                                                  maxPosition 0.044
                                                  maxForce 100
                                                }
                                                PositionSensor {
                                                  name "joint8_sensor"
                                                }
                                              ]
                                              endPoint Solid {
                                                translation 0.08657 -0.02490000050514131 -0.000244
                                                children [
                                                  Shape {
                                                    appearance DEF link8_material PBRAppearance {
                                                      roughness 1
                                                      metalness 0
                                                    }
                                                    geometry DEF link8 Mesh {
                                                      url [
                                                        "../protos/meshes/link8.STL"
                                                      ]
                                                    }
                                                  }
                                                ]
                                                name "link8"
                                                boundingObject Group {
                                                  children [
                                                    Pose {
                                                      translation 0.05 0.023 0
                                                      children [
                                                        Box {
                                                          size 0.04 0.004 0.0105
                                                        }
                                                      ]
                                                    }
                                                    Pose {
                                                      translation 0.015 0.023 0
                                                      children [
                                                        Box {
                                                          size 0.03 0.004 0.036
                                                        }
                                                      ]
                                                    }
                                                  ]
                                                }
                                                physics Physics {
                                                  density -1
                                                  mass 0.064798
                                                  centerOfMass [
                                                    -0.000355 0.007828 0.00242
                                                  ]
                                                  inertiaMatrix [
                                                    2e-05 3e-05 3e-05
                                                    0 0 0
                                                  ]
                                                }
                                              }
                                            }
                                          ]
                                          name "link6"
                                          boundingObject Pose {
                                            translation 0.03 0 0
                                            rotation 0 1 0 1.57
                                            children [
                                              Cylinder {
                                                height 0.06
                                                radius 0.03
                                              }
                                            ]
                                          }
                                          physics Physics {
                                            density -1
                                            mass 0.44089
                                            centerOfMass [
                                              0.041697 2.4e-05 0.000145
                                            ]
                                            inertiaMatrix [
                                              0.00038 0.00028 0.0005
                                              0 0 0
                                            ]
                                          }
                                        }
                                      }
                                    ]
                                    name "link5"
                                    boundingObject Pose {
                                      translation 0.005 0 0.086
                                      rotation 0 1 0 1.57
                                      children [
                                        Cylinder {
                                          height 0.04
                                          radius 0.03
                                        }
                                      ]
                                    }
                                    physics Physics {
                                      density -1
                                      mass 0.63488
                                      centerOfMass [
                                        0.003612 -1.5e-05 0.055214
                                      ]
                                      inertiaMatrix [
                                        0.00083 0.00082 0.00026
                                        0 7e-05 0
                                      ]
                                    }
                                  }
                                }
                              ]
                              name "link4"
                              boundingObject Pose {
                                translation 0.068 0 -0.066
                                children [
                                  Cylinder {
                                    height 0.04
                                    radius 0.03
                                  }
                                ]
                              }
                              physics Physics {
                                density -1
                                mass 0.11714
                                centerOfMass [
                                  0.040231 0.004481 -0.035335
                                ]
                                inertiaMatrix [
                                  0.00019 0.00023 0.00014
                                  -2e-05 -9e-05 2e-05
                                ]
                              }
                            }
                          }
                        ]
                        name "link3"
                        boundingObject Group {
                          children [
                            Pose {
                              translation 0.245 0 -0.056
                              rotation 1 0 0 1.57
                              children [
                                Cylinder {
                                  height 0.05
                                  radius 0.028
                                }
                              ]
                            }
                            Pose {
                              translation 0.135 0 -0.056
                              children [
                                Box {
                                  size 0.19 0.05 0.04
                                }
                              ]
                            }
                          ]
                        }
                        physics Physics {
                          density -1
                          mass 0.54534
                          centerOfMass [
                            0.18531 0.000684 -0.051638
                          ]
                          inertiaMatrix [
                            0.00036 0.00423 0.0042
                            -3e-05 -0.00039 1e-05
                          ]
                        }
                      }
                    }
                  ]
                  name "link2"
                  boundingObject Group {
                    children [
                      Pose {
                        rotation 1 0 0 1.57
                        children [
                          Cylinder {
                            height 0.06
                            radius 0.03
                          }
                        ]
                      }
                      Pose {
                        translation -0.13 0 0
                        children [
                          Box {
                            size 0.22 0.06 0.05
                          }
                        ]
                      }
                      Pose {
                        translation -0.26 0 0
                        rotation 1 0 0 1.57
                        children [
                          Cylinder {
                            height 0.06
                            radius 0.03
                          }
                        ]
                      }
                    ]
                  }
                  physics Physics {
                    density -1
                    mass 1.0795
                    centerOfMass [
                      -0.13237 0.002085 0.000105
                    ]
                    inertiaMatrix [
                      0.00051 0.01599 0.01605
                      1e-05 -4e-05 0
                    ]
                  }
                }
              }
            ]
            name "link1"
            physics Physics {
              density -1
              mass 0.066982
              centerOfMass [
                0.005423 -0.008029 0.017086
              ]
              inertiaMatrix [
                8e-05 3e-05 8e-05
                0 1e-05 0
              ]
            }
          }
        }
      ]
      name "link0"
      boundingObject Pose {
        translation 0 0 0.03
        children [
          Cylinder {
            height 0.06
            radius 0.03
          }
        ]
      }
      physics Physics {
        density -1
        mass 0.43995
        centerOfMass [
          -3e-05 3.1e-05 0.027324
        ]
        inertiaMatrix [
          0.00017 0.00017 0.00016
          0 0 0
        ]
      }
    }
  ]
  name "Grq20V2d3X5"
  boundingObject Group {
    children [
      Pose {
        translation 0 0 -0.01
        children [
          Box {
            size 0.42 0.26 0.18
          }
        ]
      }
      Pose {
        translation 0.32 0 0.01
        children [
          Box {
            size 0.22 0.16 0.14
          }
        ]
      }
      Pose {
        translation -0.32 0 0.01
        children [
          Box {
            size 0.22 0.16 0.14
          }
        ]
      }
      Pose {
        translation 0.27 0 0.1
        children [
          Box {
            size 0.06 0.16 0.05
          }
        ]
      }
      Pose {
        translation -0.27 0 0.1
        children [
          Box {
            size 0.06 0.16 0.05
          }
        ]
      }
    ]
  }
  controller "<extern>"
  supervisor TRUE
}
RectangleArena {
  floorSize 10 10
  floorAppearance Grass {
  }
  wallHeight 0.8
  wallAppearance Appearance {
    material Material {
      diffuseColor 0.568627 0.254902 0.67451
    }
  }
}
BiscuitBox {
  translation 1.49 -1.3 0.5
  rotation 0 0 1 -1.5707953071795862
}
CerealBox {
  translation 1.21 -1.54 0.5
  size 0.06 0.1 0.1
}
Orange {
  translation 1.39 1.34 0.55
}
Apple {
  translation 1.11 1.67 0.54
}
TrashBin {
  translation 4.36 0.569998 2.67501e-06
  rotation 1.125079999996903e-14 -2.346409999993541e-06 0.9999999999972473 3.14159
}
TrashBin {
  translation 4.36 1.53 7.18034e-06
  rotation 1.125079999996903e-14 -2.346409999993541e-06 0.9999999999972473 3.14159
  name "trash bin(1)"
  binColor 0.603922 0.6 0.588235
}
TrashBin {
  translation 4.36 -1.26 -5.91303e-06
  rotation 1.125079999996903e-14 -2.346409999993541e-06 0.9999999999972473 3.14159
  name "trash bin(2)"
  binColor 0.878431 0.105882 0.141176
}
TrashBin {
  translation 4.36 -0.320002 -1.50161e-06
  rotation 1.125079999996903e-14 -2.346409999993541e-06 0.9999999999972473 3.14159
  name "trash bin(3)"
  binColor 0.109804 0.443137 0.847059
}
Solid {
  translation 1.41 1.61 0
  children [
    Solid {
      translation 0 0 0.475
      children [
        Shape {
          appearance PBRAppearance {
            baseColor 0.141176 0.121569 0.192157
            baseColorMap ImageTexture {
              url [
                "https://raw.githubusercontent.com/cyberbotics/webots/R2025a/projects/appearances/protos/textures/varnished_pine/varnished_pine_base_color.jpg"
              ]
              filtering 5
            }
            roughnessMap ImageTexture {
              url [
                "https://raw.githubusercontent.com/cyberbotics/webots/R2025a/projects/appearances/protos/textures/varnished_pine/varnished_pine_roughness.jpg"
              ]
              filtering 5
            }
            metalness 0
            normalMap ImageTexture {
              url [
                "https://raw.githubusercontent.com/cyberbotics/webots/R2025a/projects/appearances/protos/textures/varnished_pine/varnished_pine_normal.jpg"
              ]
              filtering 5
            }
            normalMapFactor 0.5
            occlusionMap ImageTexture {
              url [
                "https://raw.githubusercontent.com/cyberbotics/webots/R2025a/projects/appearances/protos/textures/varnished_pine/varnished_pine_occlusion.jpg"
              ]
              filtering 5
            }
            textureTransform TextureTransform {
              scale 10 10
            }
          }
          geometry IndexedFaceSet {
            coord Coordinate {
              point [
                -0.4 0.4 0.025
                0.4 0.4 0.025
                0.4 0.4 -0.025
                -0.4 0.4 -0.025
                -0.4 -0.4 -0.025
                0.4 -0.4 -0.025
                0.4 -0.4 0.025
                -0.4 -0.4 0.025
                -0.4 -0.4 0.025
                0.4 -0.4 0.025
                0.4 0.4 0.025
                -0.4 0.4 0.025
                0.4 -0.4 -0.025
                -0.4 -0.4 -0.025
                -0.4 0.4 -0.025
                0.4 0.4 -0.025
                -0.4 -0.4 -0.025
                -0.4 -0.4 0.025
                -0.4 0.4 0.025
                -0.4 0.4 -0.025
                0.4 -0.4 0.025
                0.4 -0.4 -0.025
                0.4 0.4 -0.025
                0.4 0.4 0.025
              ]
            }
            texCoord TextureCoordinate {
              point [
                1 0.0625
                0 0.0625
                0 0
                1 0
                0 0
                1 0
                1 0.0625
                0 0.0625
                0 1
                0 0
                1 0
                1 1
                0 1
                0 0
                1 0
                1 1
                1 0
                1 0.0625
                0 0.0625
                0 0
                0 0.0625
                0 0
                1 0
                1 0.0625
              ]
            }
            coordIndex [
              0, 1, 2, 3, -1, 4, 5, 6, 7, -1, 8, 9, 10, 11, -1, 12, 13, 14, 15, -1, 16, 17, 18, 19, -1, 20, 21, 22, 23, -1
            ]
            creaseAngle 1.5
          }
        }
      ]
      name "main frame"
      model "box"
      boundingObject Box {
        size 0.8 0.8 0.05
      }
    }
    Solid {
      translation 0.375 0.375 0.225
      children [
        Shape {
          appearance PBRAppearance {
            baseColor 0.141176 0.121569 0.192157
            baseColorMap ImageTexture {
              url [
                "https://raw.githubusercontent.com/cyberbotics/webots/R2025a/projects/appearances/protos/textures/varnished_pine/varnished_pine_base_color.jpg"
              ]
              filtering 5
            }
            roughnessMap ImageTexture {
              url [
                "https://raw.githubusercontent.com/cyberbotics/webots/R2025a/projects/appearances/protos/textures/varnished_pine/varnished_pine_roughness.jpg"
              ]
              filtering 5
            }
            metalness 0
            normalMap ImageTexture {
              url [
                "https://raw.githubusercontent.com/cyberbotics/webots/R2025a/projects/appearances/protos/textures/varnished_pine/varnished_pine_normal.jpg"
              ]
              filtering 5
            }
            normalMapFactor 0.5
            occlusionMap ImageTexture {
              url [
                "https://raw.githubusercontent.com/cyberbotics/webots/R2025a/projects/appearances/protos/textures/varnished_pine/varnished_pine_occlusion.jpg"
              ]
              filtering 5
            }
            textureTransform TextureTransform {
              scale 4 5
            }
          }
          geometry IndexedFaceSet {
            coord Coordinate {
              point [
                -0.025 0.025 0.225
                0.025 0.025 0.225
                0.025 0.025 -0.225
                -0.025 0.025 -0.225
                -0.025 -0.025 -0.225
                0.025 -0.025 -0.225
                0.025 -0.025 0.225
                -0.025 -0.025 0.225
                -0.025 -0.025 0.225
                0.025 -0.025 0.225
                0.025 0.025 0.225
                -0.025 0.025 0.225
                0.025 -0.025 -0.225
                -0.025 -0.025 -0.225
                -0.025 0.025 -0.225
                0.025 0.025 -0.225
                -0.025 -0.025 -0.225
                -0.025 -0.025 0.225
                -0.025 0.025 0.225
                -0.025 0.025 -0.225
                0.025 -0.025 0.225
                0.025 -0.025 -0.225
                0.025 0.025 -0.225
                0.025 0.025 0.225
              ]
            }
            texCoord TextureCoordinate {
              point [
                0.11111111111111112 1
                0 1
                0 0
                0.11111111111111112 0
                0 0
                0.11111111111111112 0
                0.11111111111111112 1
                0 1
                0 0.11111111111111112
                0 0
                0.11111111111111112 0
                0.11111111111111112 0.11111111111111112
                0 0.11111111111111112
                0 0
                0.11111111111111112 0
                0.11111111111111112 0.11111111111111112
                0.11111111111111112 0
                0.11111111111111112 1
                0 1
                0 0
                0 1
                0 0
                0.11111111111111112 0
                0.11111111111111112 1
              ]
            }
            coordIndex [
              0, 1, 2, 3, -1, 4, 5, 6, 7, -1, 8, 9, 10, 11, -1, 12, 13, 14, 15, -1, 16, 17, 18, 19, -1, 20, 21, 22, 23, -1
            ]
            creaseAngle 1.5
          }
        }
      ]
      name "foot 1"
      model "box"
      boundingObject Box {
        size 0.05 0.05 0.45
      }
    }
    Solid {
      translation -0.375 0.375 0.225
      children [
        Shape {
          appearance PBRAppearance {
            baseColor 0.141176 0.121569 0.192157
            baseColorMap ImageTexture {
              url [
                "https://raw.githubusercontent.com/cyberbotics/webots/R2025a/projects/appearances/protos/textures/varnished_pine/varnished_pine_base_color.jpg"
              ]
              filtering 5
            }
            roughnessMap ImageTexture {
              url [
                "https://raw.githubusercontent.com/cyberbotics/webots/R2025a/projects/appearances/protos/textures/varnished_pine/varnished_pine_roughness.jpg"
              ]
              filtering 5
            }
            metalness 0
            normalMap ImageTexture {
              url [
                "https://raw.githubusercontent.com/cyberbotics/webots/R2025a/projects/appearances/protos/textures/varnished_pine/varnished_pine_normal.jpg"
              ]
              filtering 5
            }
            normalMapFactor 0.5
            occlusionMap ImageTexture {
              url [
                "https://raw.githubusercontent.com/cyberbotics/webots/R2025a/projects/appearances/protos/textures/varnished_pine/varnished_pine_occlusion.jpg"
              ]
              filtering 5
            }
            textureTransform TextureTransform {
              scale 4 5
            }
          }
          geometry IndexedFaceSet {
            coord Coordinate {
              point [
                -0.025 0.025 0.225
                0.025 0.025 0.225
                0.025 0.025 -0.225
                -0.025 0.025 -0.225
                -0.025 -0.025 -0.225
                0.025 -0.025 -0.225
                0.025 -0.025 0.225
                -0.025 -0.025 0.225
                -0.025 -0.025 0.225
                0.025 -0.025 0.225
                0.025 0.025 0.225
                -0.025 0.025 0.225
                0.025 -0.025 -0.225
                -0.025 -0.025 -0.225
                -0.025 0.025 -0.225
                0.025 0.025 -0.225
                -0.025 -0.025 -0.225
                -0.025 -0.025 0.225
                -0.025 0.025 0.225
                -0.025 0.025 -0.225
                0.025 -0.025 0.225
                0.025 -0.025 -0.225
                0.025 0.025 -0.225
                0.025 0.025 0.225
              ]
            }
            texCoord TextureCoordinate {
              point [
                0.11111111111111112 1
                0 1
                0 0
                0.11111111111111112 0
                0 0
                0.11111111111111112 0
                0.11111111111111112 1
                0 1
                0 0.11111111111111112
                0 0
                0.11111111111111112 0
                0.11111111111111112 0.11111111111111112
                0 0.11111111111111112
                0 0
                0.11111111111111112 0
                0.11111111111111112 0.11111111111111112
                0.11111111111111112 0
                0.11111111111111112 1
                0 1
                0 0
                0 1
                0 0
                0.11111111111111112 0
                0.11111111111111112 1
              ]
            }
            coordIndex [
              0, 1, 2, 3, -1, 4, 5, 6, 7, -1, 8, 9, 10, 11, -1, 12, 13, 14, 15, -1, 16, 17, 18, 19, -1, 20, 21, 22, 23, -1
            ]
            creaseAngle 1.5
          }
        }
      ]
      name "foot 2"
      model "box"
      boundingObject Box {
        size 0.05 0.05 0.45
      }
    }
    Solid {
      translation 0.375 -0.375 0.225
      children [
        Shape {
          appearance PBRAppearance {
            baseColor 0.141176 0.121569 0.192157
            baseColorMap ImageTexture {
              url [
                "https://raw.githubusercontent.com/cyberbotics/webots/R2025a/projects/appearances/protos/textures/varnished_pine/varnished_pine_base_color.jpg"
              ]
              filtering 5
            }
            roughnessMap ImageTexture {
              url [
                "https://raw.githubusercontent.com/cyberbotics/webots/R2025a/projects/appearances/protos/textures/varnished_pine/varnished_pine_roughness.jpg"
              ]
              filtering 5
            }
            metalness 0
            normalMap ImageTexture {
              url [
                "https://raw.githubusercontent.com/cyberbotics/webots/R2025a/projects/appearances/protos/textures/varnished_pine/varnished_pine_normal.jpg"
              ]
              filtering 5
            }
            normalMapFactor 0.5
            occlusionMap ImageTexture {
              url [
                "https://raw.githubusercontent.com/cyberbotics/webots/R2025a/projects/appearances/protos/textures/varnished_pine/varnished_pine_occlusion.jpg"
              ]
              filtering 5
            }
            textureTransform TextureTransform {
              scale 4 5
            }
          }
          geometry IndexedFaceSet {
            coord Coordinate {
              point [
                -0.025 0.025 0.225
                0.025 0.025 0.225
                0.025 0.025 -0.225
                -0.025 0.025 -0.225
                -0.025 -0.025 -0.225
                0.025 -0.025 -0.225
                0.025 -0.025 0.225
                -0.025 -0.025 0.225
                -0.025 -0.025 0.225
                0.025 -0.025 0.225
                0.025 0.025 0.225
                -0.025 0.025 0.225
                0.025 -0.025 -0.225
                -0.025 -0.025 -0.225
                -0.025 0.025 -0.225
                0.025 0.025 -0.225
                -0.025 -0.025 -0.225
                -0.025 -0.025 0.225
                -0.025 0.025 0.225
                -0.025 0.025 -0.225
                0.025 -0.025 0.225
                0.025 -0.025 -0.225
                0.025 0.025 -0.225
                0.025 0.025 0.225
              ]
            }
            texCoord TextureCoordinate {
              point [
                0.11111111111111112 1
                0 1
                0 0
                0.11111111111111112 0
                0 0
                0.11111111111111112 0
                0.11111111111111112 1
                0 1
                0 0.11111111111111112
                0 0
                0.11111111111111112 0
                0.11111111111111112 0.11111111111111112
                0 0.11111111111111112
                0 0
                0.11111111111111112 0
                0.11111111111111112 0.11111111111111112
                0.11111111111111112 0
                0.11111111111111112 1
                0 1
                0 0
                0 1
                0 0
                0.11111111111111112 0
                0.11111111111111112 1
              ]
            }
            coordIndex [
              0, 1, 2, 3, -1, 4, 5, 6, 7, -1, 8, 9, 10, 11, -1, 12, 13, 14, 15, -1, 16, 17, 18, 19, -1, 20, 21, 22, 23, -1
            ]
            creaseAngle 1.5
          }
        }
      ]
      name "foot 3"
      model "box"
      boundingObject Box {
        size 0.05 0.05 0.45
      }
    }
    Solid {
      translation -0.375 -0.375 0.225
      children [
        Shape {
          appearance PBRAppearance {
            baseColor 0.141176 0.121569 0.192157
            baseColorMap ImageTexture {
              url [
                "https://raw.githubusercontent.com/cyberbotics/webots/R2025a/projects/appearances/protos/textures/varnished_pine/varnished_pine_base_color.jpg"
              ]
              filtering 5
            }
            roughnessMap ImageTexture {
              url [
                "https://raw.githubusercontent.com/cyberbotics/webots/R2025a/projects/appearances/protos/textures/varnished_pine/varnished_pine_roughness.jpg"
              ]
              filtering 5
            }
            metalness 0
            normalMap ImageTexture {
              url [
                "https://raw.githubusercontent.com/cyberbotics/webots/R2025a/projects/appearances/protos/textures/varnished_pine/varnished_pine_normal.jpg"
              ]
              filtering 5
            }
            normalMapFactor 0.5
            occlusionMap ImageTexture {
              url [
                "https://raw.githubusercontent.com/cyberbotics/webots/R2025a/projects/appearances/protos/textures/varnished_pine/varnished_pine_occlusion.jpg"
              ]
              filtering 5
            }
            textureTransform TextureTransform {
              scale 4 5
            }
          }
          geometry IndexedFaceSet {
            coord Coordinate {
              point [
                -0.025 0.025 0.225
                0.025 0.025 0.225
                0.025 0.025 -0.225
                -0.025 0.025 -0.225
                -0.025 -0.025 -0.225
                0.025 -0.025 -0.225
                0.025 -0.025 0.225
                -0.025 -0.025 0.225
                -0.025 -0.025 0.225
                0.025 -0.025 0.225
                0.025 0.025 0.225
                -0.025 0.025 0.225
                0.025 -0.025 -0.225
                -0.025 -0.025 -0.225
                -0.025 0.025 -0.225
                0.025 0.025 -0.225
                -0.025 -0.025 -0.225
                -0.025 -0.025 0.225
                -0.025 0.025 0.225
                -0.025 0.025 -0.225
                0.025 -0.025 0.225
                0.025 -0.025 -0.225
                0.025 0.025 -0.225
                0.025 0.025 0.225
              ]
            }
            texCoord TextureCoordinate {
              point [
                0.11111111111111112 1
                0 1
                0 0
                0.11111111111111112 0
                0 0
                0.11111111111111112 0
                0.11111111111111112 1
                0 1
                0 0.11111111111111112
                0 0
                0.11111111111111112 0
                0.11111111111111112 0.11111111111111112
                0 0.11111111111111112
                0 0
                0.11111111111111112 0
                0.11111111111111112 0.11111111111111112
                0.11111111111111112 0
                0.11111111111111112 1
                0 1
                0 0
                0 1
                0 0
                0.11111111111111112 0
                0.11111111111111112 1
              ]
            }
            coordIndex [
              0, 1, 2, 3, -1, 4, 5, 6, 7, -1, 8, 9, 10, 11, -1, 12, 13, 14, 15, -1, 16, 17, 18, 19, -1, 20, 21, 22, 23, -1
            ]
            creaseAngle 1.5
          }
        }
      ]
      name "foot 4"
      model "box"
      boundingObject Box {
        size 0.05 0.05 0.45
      }
    }
  ]
  name "table"
  model "table"
}
Solid {
  translation 1.5 -1.62 0
  children [
    Solid {
      translation 0 0 0.475
      children [
        Shape {
          appearance PBRAppearance {
            baseColor 0.141176 0.121569 0.192157
            baseColorMap ImageTexture {
              url [
                "https://raw.githubusercontent.com/cyberbotics/webots/R2025a/projects/appearances/protos/textures/varnished_pine/varnished_pine_base_color.jpg"
              ]
              filtering 5
            }
            roughnessMap ImageTexture {
              url [
                "https://raw.githubusercontent.com/cyberbotics/webots/R2025a/projects/appearances/protos/textures/varnished_pine/varnished_pine_roughness.jpg"
              ]
              filtering 5
            }
            metalness 0
            normalMap ImageTexture {
              url [
                "https://raw.githubusercontent.com/cyberbotics/webots/R2025a/projects/appearances/protos/textures/varnished_pine/varnished_pine_normal.jpg"
              ]
              filtering 5
            }
            normalMapFactor 0.5
            occlusionMap ImageTexture {
              url [
                "https://raw.githubusercontent.com/cyberbotics/webots/R2025a/projects/appearances/protos/textures/varnished_pine/varnished_pine_occlusion.jpg"
              ]
              filtering 5
            }
            textureTransform TextureTransform {
              scale 10 10
            }
          }
          geometry IndexedFaceSet {
            coord Coordinate {
              point [
                -0.4 0.4 0.025
                0.4 0.4 0.025
                0.4 0.4 -0.025
                -0.4 0.4 -0.025
                -0.4 -0.4 -0.025
                0.4 -0.4 -0.025
                0.4 -0.4 0.025
                -0.4 -0.4 0.025
                -0.4 -0.4 0.025
                0.4 -0.4 0.025
                0.4 0.4 0.025
                -0.4 0.4 0.025
                0.4 -0.4 -0.025
                -0.4 -0.4 -0.025
                -0.4 0.4 -0.025
                0.4 0.4 -0.025
                -0.4 -0.4 -0.025
                -0.4 -0.4 0.025
                -0.4 0.4 0.025
                -0.4 0.4 -0.025
                0.4 -0.4 0.025
                0.4 -0.4 -0.025
                0.4 0.4 -0.025
                0.4 0.4 0.025
              ]
            }
            texCoord TextureCoordinate {
              point [
                1 0.0625
                0 0.0625
                0 0
                1 0
                0 0
                1 0
                1 0.0625
                0 0.0625
                0 1
                0 0
                1 0
                1 1
                0 1
                0 0
                1 0
                1 1
                1 0
                1 0.0625
                0 0.0625
                0 0
                0 0.0625
                0 0
                1 0
                1 0.0625
              ]
            }
            coordIndex [
              0, 1, 2, 3, -1, 4, 5, 6, 7, -1, 8, 9, 10, 11, -1, 12, 13, 14, 15, -1, 16, 17, 18, 19, -1, 20, 21, 22, 23, -1
            ]
            creaseAngle 1.5
          }
        }
      ]
      name "main frame"
      model "box"
      boundingObject Box {
        size 0.8 0.8 0.05
      }
    }
    Solid {
      translation 0.375 0.375 0.225
      children [
        Shape {
          appearance PBRAppearance {
            baseColor 0.141176 0.121569 0.192157
            baseColorMap ImageTexture {
              url [
                "https://raw.githubusercontent.com/cyberbotics/webots/R2025a/projects/appearances/protos/textures/varnished_pine/varnished_pine_base_color.jpg"
              ]
              filtering 5
            }
            roughnessMap ImageTexture {
              url [
                "https://raw.githubusercontent.com/cyberbotics/webots/R2025a/projects/appearances/protos/textures/varnished_pine/varnished_pine_roughness.jpg"
              ]
              filtering 5
            }
            metalness 0
            normalMap ImageTexture {
              url [
                "https://raw.githubusercontent.com/cyberbotics/webots/R2025a/projects/appearances/protos/textures/varnished_pine/varnished_pine_normal.jpg"
              ]
              filtering 5
            }
            normalMapFactor 0.5
            occlusionMap ImageTexture {
              url [
                "https://raw.githubusercontent.com/cyberbotics/webots/R2025a/projects/appearances/protos/textures/varnished_pine/varnished_pine_occlusion.jpg"
              ]
              filtering 5
            }
            textureTransform TextureTransform {
              scale 4 5
            }
          }
          geometry IndexedFaceSet {
            coord Coordinate {
              point [
                -0.025 0.025 0.225
                0.025 0.025 0.225
                0.025 0.025 -0.225
                -0.025 0.025 -0.225
                -0.025 -0.025 -0.225
                0.025 -0.025 -0.225
                0.025 -0.025 0.225
                -0.025 -0.025 0.225
                -0.025 -0.025 0.225
                0.025 -0.025 0.225
                0.025 0.025 0.225
                -0.025 0.025 0.225
                0.025 -0.025 -0.225
                -0.025 -0.025 -0.225
                -0.025 0.025 -0.225
                0.025 0.025 -0.225
                -0.025 -0.025 -0.225
                -0.025 -0.025 0.225
                -0.025 0.025 0.225
                -0.025 0.025 -0.225
                0.025 -0.025 0.225
                0.025 -0.025 -0.225
                0.025 0.025 -0.225
                0.025 0.025 0.225
              ]
            }
            texCoord TextureCoordinate {
              point [
                0.11111111111111112 1
                0 1
                0 0
                0.11111111111111112 0
                0 0
                0.11111111111111112 0
                0.11111111111111112 1
                0 1
                0 0.11111111111111112
                0 0
                0.11111111111111112 0
                0.11111111111111112 0.11111111111111112
                0 0.11111111111111112
                0 0
                0.11111111111111112 0
                0.11111111111111112 0.11111111111111112
                0.11111111111111112 0
                0.11111111111111112 1
                0 1
                0 0
                0 1
                0 0
                0.11111111111111112 0
                0.11111111111111112 1
              ]
            }
            coordIndex [
              0, 1, 2, 3, -1, 4, 5, 6, 7, -1, 8, 9, 10, 11, -1, 12, 13, 14, 15, -1, 16, 17, 18, 19, -1, 20, 21, 22, 23, -1
            ]
            creaseAngle 1.5
          }
        }
      ]
      name "foot 1"
      model "box"
      boundingObject Box {
        size 0.05 0.05 0.45
      }
    }
    Solid {
      translation -0.375 0.375 0.225
      children [
        Shape {
          appearance PBRAppearance {
            baseColor 0.141176 0.121569 0.192157
            baseColorMap ImageTexture {
              url [
                "https://raw.githubusercontent.com/cyberbotics/webots/R2025a/projects/appearances/protos/textures/varnished_pine/varnished_pine_base_color.jpg"
              ]
              filtering 5
            }
            roughnessMap ImageTexture {
              url [
                "https://raw.githubusercontent.com/cyberbotics/webots/R2025a/projects/appearances/protos/textures/varnished_pine/varnished_pine_roughness.jpg"
              ]
              filtering 5
            }
            metalness 0
            normalMap ImageTexture {
              url [
                "https://raw.githubusercontent.com/cyberbotics/webots/R2025a/projects/appearances/protos/textures/varnished_pine/varnished_pine_normal.jpg"
              ]
              filtering 5
            }
            normalMapFactor 0.5
            occlusionMap ImageTexture {
              url [
                "https://raw.githubusercontent.com/cyberbotics/webots/R2025a/projects/appearances/protos/textures/varnished_pine/varnished_pine_occlusion.jpg"
              ]
              filtering 5
            }
            textureTransform TextureTransform {
              scale 4 5
            }
          }
          geometry IndexedFaceSet {
            coord Coordinate {
              point [
                -0.025 0.025 0.225
                0.025 0.025 0.225
                0.025 0.025 -0.225
                -0.025 0.025 -0.225
                -0.025 -0.025 -0.225
                0.025 -0.025 -0.225
                0.025 -0.025 0.225
                -0.025 -0.025 0.225
                -0.025 -0.025 0.225
                0.025 -0.025 0.225
                0.025 0.025 0.225
                -0.025 0.025 0.225
                0.025 -0.025 -0.225
                -0.025 -0.025 -0.225
                -0.025 0.025 -0.225
                0.025 0.025 -0.225
                -0.025 -0.025 -0.225
                -0.025 -0.025 0.225
                -0.025 0.025 0.225
                -0.025 0.025 -0.225
                0.025 -0.025 0.225
                0.025 -0.025 -0.225
                0.025 0.025 -0.225
                0.025 0.025 0.225
              ]
            }
            texCoord TextureCoordinate {
              point [
                0.11111111111111112 1
                0 1
                0 0
                0.11111111111111112 0
                0 0
                0.11111111111111112 0
                0.11111111111111112 1
                0 1
                0 0.11111111111111112
                0 0
                0.11111111111111112 0
                0.11111111111111112 0.11111111111111112
                0 0.11111111111111112
                0 0
                0.11111111111111112 0
                0.11111111111111112 0.11111111111111112
                0.11111111111111112 0
                0.11111111111111112 1
                0 1
                0 0
                0 1
                0 0
                0.11111111111111112 0
                0.11111111111111112 1
              ]
            }
            coordIndex [
              0, 1, 2, 3, -1, 4, 5, 6, 7, -1, 8, 9, 10, 11, -1, 12, 13, 14, 15, -1, 16, 17, 18, 19, -1, 20, 21, 22, 23, -1
            ]
            creaseAngle 1.5
          }
        }
      ]
      name "foot 2"
      model "box"
      boundingObject Box {
        size 0.05 0.05 0.45
      }
    }
    Solid {
      translation 0.375 -0.375 0.225
      children [
        Shape {
          appearance PBRAppearance {
            baseColor 0.141176 0.121569 0.192157
            baseColorMap ImageTexture {
              url [
                "https://raw.githubusercontent.com/cyberbotics/webots/R2025a/projects/appearances/protos/textures/varnished_pine/varnished_pine_base_color.jpg"
              ]
              filtering 5
            }
            roughnessMap ImageTexture {
              url [
                "https://raw.githubusercontent.com/cyberbotics/webots/R2025a/projects/appearances/protos/textures/varnished_pine/varnished_pine_roughness.jpg"
              ]
              filtering 5
            }
            metalness 0
            normalMap ImageTexture {
              url [
                "https://raw.githubusercontent.com/cyberbotics/webots/R2025a/projects/appearances/protos/textures/varnished_pine/varnished_pine_normal.jpg"
              ]
              filtering 5
            }
            normalMapFactor 0.5
            occlusionMap ImageTexture {
              url [
                "https://raw.githubusercontent.com/cyberbotics/webots/R2025a/projects/appearances/protos/textures/varnished_pine/varnished_pine_occlusion.jpg"
              ]
              filtering 5
            }
            textureTransform TextureTransform {
              scale 4 5
            }
          }
          geometry IndexedFaceSet {
            coord Coordinate {
              point [
                -0.025 0.025 0.225
                0.025 0.025 0.225
                0.025 0.025 -0.225
                -0.025 0.025 -0.225
                -0.025 -0.025 -0.225
                0.025 -0.025 -0.225
                0.025 -0.025 0.225
                -0.025 -0.025 0.225
                -0.025 -0.025 0.225
                0.025 -0.025 0.225
                0.025 0.025 0.225
                -0.025 0.025 0.225
                0.025 -0.025 -0.225
                -0.025 -0.025 -0.225
                -0.025 0.025 -0.225
                0.025 0.025 -0.225
                -0.025 -0.025 -0.225
                -0.025 -0.025 0.225
                -0.025 0.025 0.225
                -0.025 0.025 -0.225
                0.025 -0.025 0.225
                0.025 -0.025 -0.225
                0.025 0.025 -0.225
                0.025 0.025 0.225
              ]
            }
            texCoord TextureCoordinate {
              point [
                0.11111111111111112 1
                0 1
                0 0
                0.11111111111111112 0
                0 0
                0.11111111111111112 0
                0.11111111111111112 1
                0 1
                0 0.11111111111111112
                0 0
                0.11111111111111112 0
                0.11111111111111112 0.11111111111111112
                0 0.11111111111111112
                0 0
                0.11111111111111112 0
                0.11111111111111112 0.11111111111111112
                0.11111111111111112 0
                0.11111111111111112 1
                0 1
                0 0
                0 1
                0 0
                0.11111111111111112 0
                0.11111111111111112 1
              ]
            }
            coordIndex [
              0, 1, 2, 3, -1, 4, 5, 6, 7, -1, 8, 9, 10, 11, -1, 12, 13, 14, 15, -1, 16, 17, 18, 19, -1, 20, 21, 22, 23, -1
            ]
            creaseAngle 1.5
          }
        }
      ]
      name "foot 3"
      model "box"
      boundingObject Box {
        size 0.05 0.05 0.45
      }
    }
    Solid {
      translation -0.375 -0.375 0.225
      children [
        Shape {
          appearance PBRAppearance {
            baseColor 0.141176 0.121569 0.192157
            baseColorMap ImageTexture {
              url [
                "https://raw.githubusercontent.com/cyberbotics/webots/R2025a/projects/appearances/protos/textures/varnished_pine/varnished_pine_base_color.jpg"
              ]
              filtering 5
            }
            roughnessMap ImageTexture {
              url [
                "https://raw.githubusercontent.com/cyberbotics/webots/R2025a/projects/appearances/protos/textures/varnished_pine/varnished_pine_roughness.jpg"
              ]
              filtering 5
            }
            metalness 0
            normalMap ImageTexture {
              url [
                "https://raw.githubusercontent.com/cyberbotics/webots/R2025a/projects/appearances/protos/textures/varnished_pine/varnished_pine_normal.jpg"
              ]
              filtering 5
            }
            normalMapFactor 0.5
            occlusionMap ImageTexture {
              url [
                "https://raw.githubusercontent.com/cyberbotics/webots/R2025a/projects/appearances/protos/textures/varnished_pine/varnished_pine_occlusion.jpg"
              ]
              filtering 5
            }
            textureTransform TextureTransform {
              scale 4 5
            }
          }
          geometry IndexedFaceSet {
            coord Coordinate {
              point [
                -0.025 0.025 0.225
                0.025 0.025 0.225
                0.025 0.025 -0.225
                -0.025 0.025 -0.225
                -0.025 -0.025 -0.225
                0.025 -0.025 -0.225
                0.025 -0.025 0.225
                -0.025 -0.025 0.225
                -0.025 -0.025 0.225
                0.025 -0.025 0.225
                0.025 0.025 0.225
                -0.025 0.025 0.225
                0.025 -0.025 -0.225
                -0.025 -0.025 -0.225
                -0.025 0.025 -0.225
                0.025 0.025 -0.225
                -0.025 -0.025 -0.225
                -0.025 -0.025 0.225
                -0.025 0.025 0.225
                -0.025 0.025 -0.225
                0.025 -0.025 0.225
                0.025 -0.025 -0.225
                0.025 0.025 -0.225
                0.025 0.025 0.225
              ]
            }
            texCoord TextureCoordinate {
              point [
                0.11111111111111112 1
                0 1
                0 0
                0.11111111111111112 0
                0 0
                0.11111111111111112 0
                0.11111111111111112 1
                0 1
                0 0.11111111111111112
                0 0
                0.11111111111111112 0
                0.11111111111111112 0.11111111111111112
                0 0.11111111111111112
                0 0
                0.11111111111111112 0
                0.11111111111111112 0.11111111111111112
                0.11111111111111112 0
                0.11111111111111112 1
                0 1
                0 0
                0 1
                0 0
                0.11111111111111112 0
                0.11111111111111112 1
              ]
            }
            coordIndex [
              0, 1, 2, 3, -1, 4, 5, 6, 7, -1, 8, 9, 10, 11, -1, 12, 13, 14, 15, -1, 16, 17, 18, 19, -1, 20, 21, 22, 23, -1
            ]
            creaseAngle 1.5
          }
        }
      ]
      name "foot 4"
      model "box"
      boundingObject Box {
        size 0.05 0.05 0.45
      }
    }
  ]
  name "table(1)"
  model "table"
}
Solid {
  translation -1.28 0.03 0
  children [
    Solid {
      translation 0 0 0.475
      children [
        Shape {
          appearance PBRAppearance {
            baseColor 0.141176 0.121569 0.192157
            baseColorMap ImageTexture {
              url [
                "https://raw.githubusercontent.com/cyberbotics/webots/R2025a/projects/appearances/protos/textures/varnished_pine/varnished_pine_base_color.jpg"
              ]
              filtering 5
            }
            roughnessMap ImageTexture {
              url [
                "https://raw.githubusercontent.com/cyberbotics/webots/R2025a/projects/appearances/protos/textures/varnished_pine/varnished_pine_roughness.jpg"
              ]
              filtering 5
            }
            metalness 0
            normalMap ImageTexture {
              url [
                "https://raw.githubusercontent.com/cyberbotics/webots/R2025a/projects/appearances/protos/textures/varnished_pine/varnished_pine_normal.jpg"
              ]
              filtering 5
            }
            normalMapFactor 0.5
            occlusionMap ImageTexture {
              url [
                "https://raw.githubusercontent.com/cyberbotics/webots/R2025a/projects/appearances/protos/textures/varnished_pine/varnished_pine_occlusion.jpg"
              ]
              filtering 5
            }
            textureTransform TextureTransform {
              scale 10 10
            }
          }
          geometry IndexedFaceSet {
            coord Coordinate {
              point [
                -0.4 0.4 0.025
                0.4 0.4 0.025
                0.4 0.4 -0.025
                -0.4 0.4 -0.025
                -0.4 -0.4 -0.025
                0.4 -0.4 -0.025
                0.4 -0.4 0.025
                -0.4 -0.4 0.025
                -0.4 -0.4 0.025
                0.4 -0.4 0.025
                0.4 0.4 0.025
                -0.4 0.4 0.025
                0.4 -0.4 -0.025
                -0.4 -0.4 -0.025
                -0.4 0.4 -0.025
                0.4 0.4 -0.025
                -0.4 -0.4 -0.025
                -0.4 -0.4 0.025
                -0.4 0.4 0.025
                -0.4 0.4 -0.025
                0.4 -0.4 0.025
                0.4 -0.4 -0.025
                0.4 0.4 -0.025
                0.4 0.4 0.025
              ]
            }
            texCoord TextureCoordinate {
              point [
                1 0.0625
                0 0.0625
                0 0
                1 0
                0 0
                1 0
                1 0.0625
                0 0.0625
                0 1
                0 0
                1 0
                1 1
                0 1
                0 0
                1 0
                1 1
                1 0
                1 0.0625
                0 0.0625
                0 0
                0 0.0625
                0 0
                1 0
                1 0.0625
              ]
            }
            coordIndex [
              0, 1, 2, 3, -1, 4, 5, 6, 7, -1, 8, 9, 10, 11, -1, 12, 13, 14, 15, -1, 16, 17, 18, 19, -1, 20, 21, 22, 23, -1
            ]
            creaseAngle 1.5
          }
        }
      ]
      name "main frame"
      model "box"
      boundingObject Box {
        size 0.8 0.8 0.05
      }
    }
    Solid {
      translation 0.375 0.375 0.225
      children [
        Shape {
          appearance PBRAppearance {
            baseColor 0.141176 0.121569 0.192157
            baseColorMap ImageTexture {
              url [
                "https://raw.githubusercontent.com/cyberbotics/webots/R2025a/projects/appearances/protos/textures/varnished_pine/varnished_pine_base_color.jpg"
              ]
              filtering 5
            }
            roughnessMap ImageTexture {
              url [
                "https://raw.githubusercontent.com/cyberbotics/webots/R2025a/projects/appearances/protos/textures/varnished_pine/varnished_pine_roughness.jpg"
              ]
              filtering 5
            }
            metalness 0
            normalMap ImageTexture {
              url [
                "https://raw.githubusercontent.com/cyberbotics/webots/R2025a/projects/appearances/protos/textures/varnished_pine/varnished_pine_normal.jpg"
              ]
              filtering 5
            }
            normalMapFactor 0.5
            occlusionMap ImageTexture {
              url [
                "https://raw.githubusercontent.com/cyberbotics/webots/R2025a/projects/appearances/protos/textures/varnished_pine/varnished_pine_occlusion.jpg"
              ]
              filtering 5
            }
            textureTransform TextureTransform {
              scale 4 5
            }
          }
          geometry IndexedFaceSet {
            coord Coordinate {
              point [
                -0.025 0.025 0.225
                0.025 0.025 0.225
                0.025 0.025 -0.225
                -0.025 0.025 -0.225
                -0.025 -0.025 -0.225
                0.025 -0.025 -0.225
                0.025 -0.025 0.225
                -0.025 -0.025 0.225
                -0.025 -0.025 0.225
                0.025 -0.025 0.225
                0.025 0.025 0.225
                -0.025 0.025 0.225
                0.025 -0.025 -0.225
                -0.025 -0.025 -0.225
                -0.025 0.025 -0.225
                0.025 0.025 -0.225
                -0.025 -0.025 -0.225
                -0.025 -0.025 0.225
                -0.025 0.025 0.225
                -0.025 0.025 -0.225
                0.025 -0.025 0.225
                0.025 -0.025 -0.225
                0.025 0.025 -0.225
                0.025 0.025 0.225
              ]
            }
            texCoord TextureCoordinate {
              point [
                0.11111111111111112 1
                0 1
                0 0
                0.11111111111111112 0
                0 0
                0.11111111111111112 0
                0.11111111111111112 1
                0 1
                0 0.11111111111111112
                0 0
                0.11111111111111112 0
                0.11111111111111112 0.11111111111111112
                0 0.11111111111111112
                0 0
                0.11111111111111112 0
                0.11111111111111112 0.11111111111111112
                0.11111111111111112 0
                0.11111111111111112 1
                0 1
                0 0
                0 1
                0 0
                0.11111111111111112 0
                0.11111111111111112 1
              ]
            }
            coordIndex [
              0, 1, 2, 3, -1, 4, 5, 6, 7, -1, 8, 9, 10, 11, -1, 12, 13, 14, 15, -1, 16, 17, 18, 19, -1, 20, 21, 22, 23, -1
            ]
            creaseAngle 1.5
          }
        }
      ]
      name "foot 1"
      model "box"
      boundingObject Box {
        size 0.05 0.05 0.45
      }
    }
    Solid {
      translation -0.375 0.375 0.225
      children [
        Shape {
          appearance PBRAppearance {
            baseColor 0.141176 0.121569 0.192157
            baseColorMap ImageTexture {
              url [
                "https://raw.githubusercontent.com/cyberbotics/webots/R2025a/projects/appearances/protos/textures/varnished_pine/varnished_pine_base_color.jpg"
              ]
              filtering 5
            }
            roughnessMap ImageTexture {
              url [
                "https://raw.githubusercontent.com/cyberbotics/webots/R2025a/projects/appearances/protos/textures/varnished_pine/varnished_pine_roughness.jpg"
              ]
              filtering 5
            }
            metalness 0
            normalMap ImageTexture {
              url [
                "https://raw.githubusercontent.com/cyberbotics/webots/R2025a/projects/appearances/protos/textures/varnished_pine/varnished_pine_normal.jpg"
              ]
              filtering 5
            }
            normalMapFactor 0.5
            occlusionMap ImageTexture {
              url [
                "https://raw.githubusercontent.com/cyberbotics/webots/R2025a/projects/appearances/protos/textures/varnished_pine/varnished_pine_occlusion.jpg"
              ]
              filtering 5
            }
            textureTransform TextureTransform {
              scale 4 5
            }
          }
          geometry IndexedFaceSet {
            coord Coordinate {
              point [
                -0.025 0.025 0.225
                0.025 0.025 0.225
                0.025 0.025 -0.225
                -0.025 0.025 -0.225
                -0.025 -0.025 -0.225
                0.025 -0.025 -0.225
                0.025 -0.025 0.225
                -0.025 -0.025 0.225
                -0.025 -0.025 0.225
                0.025 -0.025 0.225
                0.025 0.025 0.225
                -0.025 0.025 0.225
                0.025 -0.025 -0.225
                -0.025 -0.025 -0.225
                -0.025 0.025 -0.225
                0.025 0.025 -0.225
                -0.025 -0.025 -0.225
                -0.025 -0.025 0.225
                -0.025 0.025 0.225
                -0.025 0.025 -0.225
                0.025 -0.025 0.225
                0.025 -0.025 -0.225
                0.025 0.025 -0.225
                0.025 0.025 0.225
              ]
            }
            texCoord TextureCoordinate {
              point [
                0.11111111111111112 1
                0 1
                0 0
                0.11111111111111112 0
                0 0
                0.11111111111111112 0
                0.11111111111111112 1
                0 1
                0 0.11111111111111112
                0 0
                0.11111111111111112 0
                0.11111111111111112 0.11111111111111112
                0 0.11111111111111112
                0 0
                0.11111111111111112 0
                0.11111111111111112 0.11111111111111112
                0.11111111111111112 0
                0.11111111111111112 1
                0 1
                0 0
                0 1
                0 0
                0.11111111111111112 0
                0.11111111111111112 1
              ]
            }
            coordIndex [
              0, 1, 2, 3, -1, 4, 5, 6, 7, -1, 8, 9, 10, 11, -1, 12, 13, 14, 15, -1, 16, 17, 18, 19, -1, 20, 21, 22, 23, -1
            ]
            creaseAngle 1.5
          }
        }
      ]
      name "foot 2"
      model "box"
      boundingObject Box {
        size 0.05 0.05 0.45
      }
    }
    Solid {
      translation 0.375 -0.375 0.225
      children [
        Shape {
          appearance PBRAppearance {
            baseColor 0.141176 0.121569 0.192157
            baseColorMap ImageTexture {
              url [
                "https://raw.githubusercontent.com/cyberbotics/webots/R2025a/projects/appearances/protos/textures/varnished_pine/varnished_pine_base_color.jpg"
              ]
              filtering 5
            }
            roughnessMap ImageTexture {
              url [
                "https://raw.githubusercontent.com/cyberbotics/webots/R2025a/projects/appearances/protos/textures/varnished_pine/varnished_pine_roughness.jpg"
              ]
              filtering 5
            }
            metalness 0
            normalMap ImageTexture {
              url [
                "https://raw.githubusercontent.com/cyberbotics/webots/R2025a/projects/appearances/protos/textures/varnished_pine/varnished_pine_normal.jpg"
              ]
              filtering 5
            }
            normalMapFactor 0.5
            occlusionMap ImageTexture {
              url [
                "https://raw.githubusercontent.com/cyberbotics/webots/R2025a/projects/appearances/protos/textures/varnished_pine/varnished_pine_occlusion.jpg"
              ]
              filtering 5
            }
            textureTransform TextureTransform {
              scale 4 5
            }
          }
          geometry IndexedFaceSet {
            coord Coordinate {
              point [
                -0.025 0.025 0.225
                0.025 0.025 0.225
                0.025 0.025 -0.225
                -0.025 0.025 -0.225
                -0.025 -0.025 -0.225
                0.025 -0.025 -0.225
                0.025 -0.025 0.225
                -0.025 -0.025 0.225
                -0.025 -0.025 0.225
                0.025 -0.025 0.225
                0.025 0.025 0.225
                -0.025 0.025 0.225
                0.025 -0.025 -0.225
                -0.025 -0.025 -0.225
                -0.025 0.025 -0.225
                0.025 0.025 -0.225
                -0.025 -0.025 -0.225
                -0.025 -0.025 0.225
                -0.025 0.025 0.225
                -0.025 0.025 -0.225
                0.025 -0.025 0.225
                0.025 -0.025 -0.225
                0.025 0.025 -0.225
                0.025 0.025 0.225
              ]
            }
            texCoord TextureCoordinate {
              point [
                0.11111111111111112 1
                0 1
                0 0
                0.11111111111111112 0
                0 0
                0.11111111111111112 0
                0.11111111111111112 1
                0 1
                0 0.11111111111111112
                0 0
                0.11111111111111112 0
                0.11111111111111112 0.11111111111111112
                0 0.11111111111111112
                0 0
                0.11111111111111112 0
                0.11111111111111112 0.11111111111111112
                0.11111111111111112 0
                0.11111111111111112 1
                0 1
                0 0
                0 1
                0 0
                0.11111111111111112 0
                0.11111111111111112 1
              ]
            }
            coordIndex [
              0, 1, 2, 3, -1, 4, 5, 6, 7, -1, 8, 9, 10, 11, -1, 12, 13, 14, 15, -1, 16, 17, 18, 19, -1, 20, 21, 22, 23, -1
            ]
            creaseAngle 1.5
          }
        }
      ]
      name "foot 3"
      model "box"
      boundingObject Box {
        size 0.05 0.05 0.45
      }
    }
    Solid {
      translation -0.375 -0.375 0.225
      children [
        Shape {
          appearance PBRAppearance {
            baseColor 0.141176 0.121569 0.192157
            baseColorMap ImageTexture {
              url [
                "https://raw.githubusercontent.com/cyberbotics/webots/R2025a/projects/appearances/protos/textures/varnished_pine/varnished_pine_base_color.jpg"
              ]
              filtering 5
            }
            roughnessMap ImageTexture {
              url [
                "https://raw.githubusercontent.com/cyberbotics/webots/R2025a/projects/appearances/protos/textures/varnished_pine/varnished_pine_roughness.jpg"
              ]
              filtering 5
            }
            metalness 0
            normalMap ImageTexture {
              url [
                "https://raw.githubusercontent.com/cyberbotics/webots/R2025a/projects/appearances/protos/textures/varnished_pine/varnished_pine_normal.jpg"
              ]
              filtering 5
            }
            normalMapFactor 0.5
            occlusionMap ImageTexture {
              url [
                "https://raw.githubusercontent.com/cyberbotics/webots/R2025a/projects/appearances/protos/textures/varnished_pine/varnished_pine_occlusion.jpg"
              ]
              filtering 5
            }
            textureTransform TextureTransform {
              scale 4 5
            }
          }
          geometry IndexedFaceSet {
            coord Coordinate {
              point [
                -0.025 0.025 0.225
                0.025 0.025 0.225
                0.025 0.025 -0.225
                -0.025 0.025 -0.225
                -0.025 -0.025 -0.225
                0.025 -0.025 -0.225
                0.025 -0.025 0.225
                -0.025 -0.025 0.225
                -0.025 -0.025 0.225
                0.025 -0.025 0.225
                0.025 0.025 0.225
                -0.025 0.025 0.225
                0.025 -0.025 -0.225
                -0.025 -0.025 -0.225
                -0.025 0.025 -0.225
                0.025 0.025 -0.225
                -0.025 -0.025 -0.225
                -0.025 -0.025 0.225
                -0.025 0.025 0.225
                -0.025 0.025 -0.225
                0.025 -0.025 0.225
                0.025 -0.025 -0.225
                0.025 0.025 -0.225
                0.025 0.025 0.225
              ]
            }
            texCoord TextureCoordinate {
              point [
                0.11111111111111112 1
                0 1
                0 0
                0.11111111111111112 0
                0 0
                0.11111111111111112 0
                0.11111111111111112 1
                0 1
                0 0.11111111111111112
                0 0
                0.11111111111111112 0
                0.11111111111111112 0.11111111111111112
                0 0.11111111111111112
                0 0
                0.11111111111111112 0
                0.11111111111111112 0.11111111111111112
                0.11111111111111112 0
                0.11111111111111112 1
                0 1
                0 0
                0 1
                0 0
                0.11111111111111112 0
                0.11111111111111112 1
              ]
            }
            coordIndex [
              0, 1, 2, 3, -1, 4, 5, 6, 7, -1, 8, 9, 10, 11, -1, 12, 13, 14, 15, -1, 16, 17, 18, 19, -1, 20, 21, 22, 23, -1
            ]
            creaseAngle 1.5
          }
        }
      ]
      name "foot 4"
      model "box"
      boundingObject Box {
        size 0.05 0.05 0.45
      }
    }
  ]
  name "table(2)"
  model "table"
}
Chair {
  translation 2.32 -1.64 0
  rotation 0 0 1 3.14159
  color 0.141176 0.121569 0.192157
}
Chair {
  translation 2.23 1.65 0
  rotation 0 0 1 3.14159
  name "chair(1)"
  color 0.141176 0.121569 0.192157
}
Chair {
  translation -1.32 0.84 0
  rotation 0 0 1 -1.5707953071795862
  name "chair(4)"
  color 0.141176 0.121569 0.192157
}
Chair {
  translation -2.12 0.04 0
  rotation 0 0 1 1.01503e-06
  name "chair(5)"
  color 0.141176 0.121569 0.192157
}
Chair {
  translation 1.4 2.5 0
  rotation 0 0 1 -1.5707953071795862
  name "chair(2)"
  color 0.141176 0.121569 0.192157
}
Chair {
  translation 1.48 -2.54 0
  rotation 0 0 1 1.5708
  name "chair(3)"
  color 0.141176 0.121569 0.192157
}
Solid {
  translation 1.13 1.34 0.5
  children [
    CadShape {
      url [
        "../protos/obj_assert/banana/banana.obj"
      ]
    }
  ]
  name "banana"
}
Solid {
  translation 1.23 -1.88 0.5
  children [
    CadShape {
      url [
        "../protos/obj_assert/Box/Box.obj"
        ""
        ""
      ]
    }
  ]
  name "box"
}
BeerBottle {
  translation -1.35 -0.23 0.5
}
DEF flacon MedicineBottle {
  translation -1.13 -0.25 0.54
}
DEF flacon MedicineBottle {
  translation -1 -0.06 0.54
  name "medicine bottle(1)"
}
