#VRML_SIM R2025a utf8

EXTERNPROTO "https://raw.githubusercontent.com/cyberbotics/webots/R2025a/projects/objects/backgrounds/protos/TexturedBackground.proto"
EXTERNPROTO "https://raw.githubusercontent.com/cyberbotics/webots/R2025a/projects/objects/backgrounds/protos/TexturedBackgroundLight.proto"
EXTERNPROTO "https://raw.githubusercontent.com/cyberbotics/webots/R2025a/projects/appearances/protos/BrushedAluminium.proto"
EXTERNPROTO "https://raw.githubusercontent.com/cyberbotics/webots/R2025a/projects/objects/floors/protos/Floor.proto"
EXTERNPROTO "https://raw.githubusercontent.com/cyberbotics/webots/R2025a/projects/objects/solids/protos/SolidBox.proto"

WorldInfo {
  basicTimeStep 2
}
Viewpoint {
  orientation 0.23191091936950645 0.12818511000709387 -0.9642540656122014 2.1622218938414925
  position 1.8730852032549323 3.5486661247619455 2.3075765194615556
}
TexturedBackground {
}
TexturedBackgroundLight {
}
Solid {
  children [
    Floor {
    }
    SolidBox {
      translation 5.005 0 0.05
      name "wall"
      size 0.01 10 0.1
      appearance BrushedAluminium {
      }
    }
    SolidBox {
      translation -5.005 0 0.05
      name "wall#2"
      size 0.01 10 0.1
      appearance BrushedAluminium {
      }
    }
    SolidBox {
      translation 0 5.005 0.05
      name "wall#3"
      size 10.02 0.01 0.1
      appearance BrushedAluminium {
      }
    }
    SolidBox {
      translation 0 -5.005 0.05
      name "wall#4"
      size 10.02 0.01 0.1
      appearance BrushedAluminium {
      }
    }
  ]
  name "rectangle arena"
  model "rectangle arena"
}
Robot {
  translation 0.0008683442228777866 -0.0002728399057587193 0.3677833277595379
  rotation 0.2991695417860289 0.9541997496344319 0.0006504345663648261 0.0023752137742080338
  children [
    Shape {
      appearance DEF base_link_material PBRAppearance {
        baseColor 0.8 0.4 0
        roughness 1
        metalness 0
      }
      geometry DEF TRUCK Mesh {
        url [
          "../protos/meshes/TRUCK.STL"
        ]
      }
    }
    HingeJoint {
      jointParameters HingeJointParameters {
        position 1.308799859171947e-05
        anchor 0.2987 0.06 0
      }
      device [
        RotationalMotor {
          name "FL_hip_joint"
          maxVelocity 22
          minPosition -0.741764919444444
          maxPosition 0.741764919444444
          maxTorque 150
        }
        PositionSensor {
          name "FL_hip_joint_sensor"
        }
      ]
      endPoint Solid {
        translation 0.2987 0.06 0
        rotation 1 0 0 1.3088004675305432e-05
        children [
          Shape {
            appearance DEF FL_hip_material PBRAppearance {
              baseColor 1 0.4 0.4
              roughness 1
              metalness 0
            }
            geometry DEF FL_HIP Mesh {
              url [
                "../protos/meshes/FL_HIP.STL"
              ]
            }
          }
          HingeJoint {
            jointParameters HingeJointParameters {
              position 0.8399986661429388
              axis 0 1 0
              anchor 0 0.1341 0
            }
            device [
              RotationalMotor {
                name "FL_thigh_joint"
                maxVelocity 22
                minPosition -1.22173
                maxPosition 3.8397
                maxTorque 150
              }
              PositionSensor {
                name "FL_thigh_joint_sensor"
              }
            ]
            endPoint Solid {
              translation 0 0.1341 0
              rotation 0 0.9999999999999999 0 0.8399986661429386
              children [
                Shape {
                  appearance DEF FL_thigh_material PBRAppearance {
                    baseColor 1 1 0.4
                    roughness 1
                    metalness 0
                  }
                  geometry DEF FL_THIGH Mesh {
                    url [
                      "../protos/meshes/FL_THIGH.STL"
                    ]
                  }
                }
                HingeJoint {
                  jointParameters HingeJointParameters {
                    position -1.6100222034481237
                    axis 0 1 0
                    anchor 0 0 -0.26
                  }
                  device [
                    RotationalMotor {
                      name "FL_calf_joint"
                      maxVelocity 22
                      minPosition -2.77507346333333
                      maxPosition -0.541052058888889
                      maxTorque 150
                    }
                    PositionSensor {
                      name "FL_calf_joint_sensor"
                    }
                  ]
                  endPoint Solid {
                    translation 0 0 -0.26
                    rotation 0 -1 0 1.6100222034481237
                    children [
                      Shape {
                        appearance DEF FL_calf_material PBRAppearance {
                          baseColor 0.4 1 0.4
                          roughness 1
                          metalness 0
                        }
                        geometry DEF FL_CALF Mesh {
                          url [
                            "../protos/meshes/FL_CALF.STL"
                          ]
                        }
                      }
                      Solid {
                        translation 0 0 -0.26149
                        children [
                          Shape {
                            appearance DEF FL_foot_material PBRAppearance {
                              baseColor 0 0.5 1
                              roughness 1
                              metalness 0
                            }
                            geometry Sphere {
                              radius 0.026
                            }
                          }
                        ]
                        name "FL_foot"
                        boundingObject Sphere {
                          radius 0.026
                        }
                        physics Physics {
                          density -1
                          mass 0.000205
                          centerOfMass [
                            0 0 0
                          ]
                          inertiaMatrix [
                            1.096001e-09 1.096001e-09 1.096001e-09
                            0 0 0
                          ]
                        }
                      }
                    ]
                    name "FL_calf"
                    boundingObject Group {
                      children [
                        Pose {
                          translation 0.00919 0 -0.06536
                          rotation 0 -1 0 0.139626
                          children [
                            Box {
                              size 0.033 0.033 0.23
                            }
                          ]
                        }
                        Pose {
                          translation 0.01381 0 -0.21574
                          rotation 0 1 0 0.24103
                          children [
                            Box {
                              size 0.036 0.036 0.09273
                            }
                          ]
                        }
                      ]
                    }
                    physics Physics {
                      density -1
                      mass 0.302786
                      centerOfMass [
                        0.008 0.003625 -0.128915
                      ]
                      inertiaMatrix [
                        0.0085187 0.0085725 0.0001128
                        8.6e-06 0.0003718 0.0001434
                      ]
                    }
                  }
                }
              ]
              name "FL_thigh"
              boundingObject Group {
                children [
                  Pose {
                    translation 0 -0.02125 0
                    rotation 0.5775032287046065 0.5775032287046065 -0.5770442285228318 2.093475
                    children [
                      Cylinder {
                        height 0.085
                        radius 0.058
                      }
                    ]
                  }
                  Pose {
                    translation -0.02158 0 -0.09691
                    rotation 0 1 0 0.122173
                    children [
                      Box {
                        size 0.06368 0.036 0.19764
                      }
                    ]
                  }
                  Pose {
                    translation -0.01645 0 -0.23181
                    rotation 0 -1 0 0.436332
                    children [
                      Box {
                        size 0.054 0.036 0.115
                      }
                    ]
                  }
                ]
              }
              physics Physics {
                density -1
                mass 2.930464
                centerOfMass [
                  -0.003481 -0.032125 -0.031894
                ]
                inertiaMatrix [
                  0.0264127 0.0232267 0.0081071
                  5.18e-05 0.0012845 0.0002853
                ]
              }
            }
          }
        ]
        name "FL_hip"
        physics Physics {
          density -1
          mass 1.87369
          centerOfMass [
            -0.002155 0.006319 1e-06
          ]
          inertiaMatrix [
            0.0021359 0.0034595 0.002322
            2.5e-05 0 0
          ]
        }
      }
    }
    HingeJoint {
      jointParameters HingeJointParameters {
        position 1.1762725871449206e-05
        anchor -0.2987 0.06 0
      }
      device [
        RotationalMotor {
          name "RL_hip_joint"
          maxVelocity 22
          minPosition -0.741764919444444
          maxPosition 0.741764919444444
          maxTorque 150
        }
        PositionSensor {
          name "RL_hip_joint_sensor"
        }
      ]
      endPoint Solid {
        translation -0.2987 0.06 0
        rotation 1 0 0 1.1762708973689013e-05
        children [
          Shape {
            appearance DEF RL_hip_material PBRAppearance {
              baseColor 0.8 1 0.8
              roughness 1
              metalness 0
            }
            geometry DEF RL_HIP Mesh {
              url [
                "../protos/meshes/RL_HIP.STL"
              ]
            }
          }
          HingeJoint {
            jointParameters HingeJointParameters {
              position 0.8400013783295616
              axis 0 1 0
              anchor 0 0.1341 0
            }
            device [
              RotationalMotor {
                name "RL_thigh_joint"
                maxVelocity 22
                minPosition -1.22173
                maxPosition 3.8397
                maxTorque 150
              }
              PositionSensor {
                name "RL_thigh_joint_sensor"
              }
            ]
            endPoint Solid {
              translation 0 0.1341 0
              rotation 0 1 0 0.8400013783295613
              children [
                Shape {
                  appearance DEF RL_thigh_material PBRAppearance {
                    baseColor 1 0.5 1
                    roughness 1
                    metalness 0
                  }
                  geometry USE FL_THIGH
                }
                HingeJoint {
                  jointParameters HingeJointParameters {
                    position -1.6100204516638372
                    axis 0 1 0
                    anchor 0 0 -0.26
                  }
                  device [
                    RotationalMotor {
                      name "RL_calf_joint"
                      maxVelocity 22
                      minPosition -2.77507346333333
                      maxPosition -0.541052058888889
                      maxTorque 150
                    }
                    PositionSensor {
                      name "RL_calf_joint_sensor"
                    }
                  ]
                  endPoint Solid {
                    translation 0 0 -0.26
                    rotation 0 -1 0 1.610020451663837
                    children [
                      Shape {
                        appearance DEF RL_calf_material PBRAppearance {
                          baseColor 1 0.4 0.4
                          roughness 1
                          metalness 0
                        }
                        geometry USE FL_CALF
                      }
                      Solid {
                        translation 0 0 -0.26149
                        children [
                          Shape {
                            appearance DEF RL_foot_material PBRAppearance {
                              baseColor 1 1 0.4
                              roughness 1
                              metalness 0
                            }
                            geometry Sphere {
                              radius 0.026
                            }
                          }
                        ]
                        name "RL_foot"
                        boundingObject Sphere {
                          radius 0.026
                        }
                        physics Physics {
                          density -1
                          mass 0.000205
                          centerOfMass [
                            0 0 0
                          ]
                          inertiaMatrix [
                            1.096001e-09 1.096001e-09 1.096001e-09
                            0 0 0
                          ]
                        }
                      }
                    ]
                    name "RL_calf"
                    boundingObject Group {
                      children [
                        Pose {
                          translation 0.00919 0 -0.06536
                          rotation 0 -1 0 0.139626
                          children [
                            Box {
                              size 0.033 0.033 0.23
                            }
                          ]
                        }
                        Pose {
                          translation 0.01381 0 -0.21574
                          rotation 0 1 0 0.24103
                          children [
                            Box {
                              size 0.036 0.036 0.09273
                            }
                          ]
                        }
                      ]
                    }
                    physics Physics {
                      density -1
                      mass 0.302786
                      centerOfMass [
                        0.008 0.003625 -0.128915
                      ]
                      inertiaMatrix [
                        0.0085187 0.0085725 0.0001128
                        8.6e-06 0.0003718 0.0001434
                      ]
                    }
                  }
                }
              ]
              name "RL_thigh"
              boundingObject Group {
                children [
                  Pose {
                    translation 0 -0.02125 0
                    rotation 0.5775032287046065 0.5775032287046065 -0.5770442285228318 2.093475
                    children [
                      Cylinder {
                        height 0.085
                        radius 0.058
                      }
                    ]
                  }
                  Pose {
                    translation -0.02158 0 -0.09691
                    rotation 0 1 0 0.122173
                    children [
                      Box {
                        size 0.06368 0.036 0.19764
                      }
                    ]
                  }
                  Pose {
                    translation -0.01645 0 -0.23181
                    rotation 0 -1 0 0.436332
                    children [
                      Box {
                        size 0.054 0.036 0.115
                      }
                    ]
                  }
                ]
              }
              physics Physics {
                density -1
                mass 2.930464
                centerOfMass [
                  -0.003481 -0.032125 -0.031894
                ]
                inertiaMatrix [
                  0.0264127 0.0232267 0.0081071
                  5.18e-05 0.0012845 0.0002853
                ]
              }
            }
          }
        ]
        name "RL_hip"
        physics Physics {
          density -1
          mass 1.87369
          centerOfMass [
            -0.002155 0.006319 1e-06
          ]
          inertiaMatrix [
            0.0021359 0.0034595 0.002322
            2.5e-05 0 0
          ]
        }
      }
    }
    HingeJoint {
      jointParameters HingeJointParameters {
        position -1.3608479112470206e-05
        anchor 0.2987 -0.06 0
      }
      device [
        RotationalMotor {
          name "FR_hip_joint"
          maxVelocity 22
          minPosition -0.741764919444444
          maxPosition 0.741764919444444
          maxTorque 150
        }
        PositionSensor {
          name "FR_hip_joint_sensor"
        }
      ]
      endPoint Solid {
        translation 0.2987 -0.06 0
        rotation -0.9999999999999999 0 0 1.3608472712935453e-05
        children [
          Transform {
            scale 1 -1 1
            children [
              Shape {
                appearance DEF FR_hip_material PBRAppearance {
                  baseColor 1 0.4 0.4
                  roughness 1
                  metalness 0
                }
                geometry DEF FL_HIP_cw Mesh {
                  url [
                    "../protos/meshes/FL_HIP.STL"
                  ]
                  ccw FALSE
                }
              }
            ]
          }
          HingeJoint {
            jointParameters HingeJointParameters {
              position 0.8400012168061004
              axis 0 1 0
              anchor 0 -0.1341 0
            }
            device [
              RotationalMotor {
                name "FR_thigh_joint"
                maxVelocity 22
                minPosition -1.22173
                maxPosition 3.8397
                maxTorque 150
              }
              PositionSensor {
                name "FR_thigh_joint_sensor"
              }
            ]
            endPoint Solid {
              translation 0 -0.1341 0
              rotation 0 1 0 0.8400012168061004
              children [
                Transform {
                  scale 1 -1 1
                  children [
                    Shape {
                      appearance DEF FR_thigh_material PBRAppearance {
                        baseColor 1 1 0.4
                        roughness 1
                        metalness 0
                      }
                      geometry DEF FL_THIGH_cw Mesh {
                        url [
                          "../protos/meshes/FL_THIGH.STL"
                        ]
                        ccw FALSE
                      }
                    }
                  ]
                }
                HingeJoint {
                  jointParameters HingeJointParameters {
                    position -1.6100229361313694
                    axis 0 1 0
                    anchor 0 0 -0.26
                  }
                  device [
                    RotationalMotor {
                      name "FR_calf_joint"
                      maxVelocity 22
                      minPosition -2.77507346333333
                      maxPosition -0.541052058888889
                      maxTorque 150
                    }
                    PositionSensor {
                      name "FR_calf_joint_sensor"
                    }
                  ]
                  endPoint Solid {
                    translation 0 0 -0.26
                    rotation 0 -1 0 1.6100229361313694
                    children [
                      Transform {
                        scale 1 -1 1
                        children [
                          Shape {
                            appearance DEF FR_calf_material PBRAppearance {
                              baseColor 0.4 1 0.4
                              roughness 1
                              metalness 0
                            }
                            geometry DEF FL_CALF_cw Mesh {
                              url [
                                "../protos/meshes/FL_CALF.STL"
                              ]
                              ccw FALSE
                            }
                          }
                        ]
                      }
                      Solid {
                        translation 0 0 -0.26149
                        children [
                          Shape {
                            appearance DEF FR_foot_material PBRAppearance {
                              baseColor 0 0.5 1
                              roughness 1
                              metalness 0
                            }
                            geometry Sphere {
                              radius 0.026
                            }
                          }
                        ]
                        name "FR_foot"
                        boundingObject Sphere {
                          radius 0.026
                        }
                        physics Physics {
                          density -1
                          mass 0.000205
                          centerOfMass [
                            0 0 0
                          ]
                          inertiaMatrix [
                            1.096001e-09 1.096001e-09 1.096001e-09
                            0 0 0
                          ]
                        }
                      }
                    ]
                    name "FR_calf"
                    boundingObject Group {
                      children [
                        Pose {
                          translation 0.00919 0 -0.06536
                          rotation 0 -1 0 0.139626
                          children [
                            Box {
                              size 0.033 0.033 0.23
                            }
                          ]
                        }
                        Pose {
                          translation 0.01381 0 -0.21574
                          rotation 0 1 0 0.24103
                          children [
                            Box {
                              size 0.036 0.036 0.09273
                            }
                          ]
                        }
                      ]
                    }
                    physics Physics {
                      density -1
                      mass 0.302786
                      centerOfMass [
                        0.008 -0.003625 -0.128915
                      ]
                      inertiaMatrix [
                        0.0085187 0.0085725 0.0001128
                        -8.6e-06 0.0003718 -0.0001434
                      ]
                    }
                  }
                }
              ]
              name "FR_thigh"
              boundingObject Group {
                children [
                  Pose {
                    translation 0 0.02125 0
                    rotation 0.5775032287046065 0.5775032287046065 -0.5770442285228318 2.093475
                    children [
                      Cylinder {
                        height 0.085
                        radius 0.058
                      }
                    ]
                  }
                  Pose {
                    translation -0.02158 0 -0.09691
                    rotation 0 1 0 0.122173
                    children [
                      Box {
                        size 0.06368 0.036 0.19764
                      }
                    ]
                  }
                  Pose {
                    translation -0.01645 0 -0.23181
                    rotation 0 -1 0 0.436332
                    children [
                      Box {
                        size 0.054 0.036 0.115
                      }
                    ]
                  }
                ]
              }
              physics Physics {
                density -1
                mass 2.930464
                centerOfMass [
                  -0.003481 0.032125 -0.031894
                ]
                inertiaMatrix [
                  0.0264127 0.0232267 0.0081071
                  -5.18e-05 0.0012845 -0.0002853
                ]
              }
            }
          }
        ]
        name "FR_hip"
        physics Physics {
          density -1
          mass 1.87369
          centerOfMass [
            -0.002155 -0.006319 1e-06
          ]
          inertiaMatrix [
            0.0021359 0.0034595 0.002322
            -2.5e-05 0 0
          ]
        }
      }
    }
    HingeJoint {
      jointParameters HingeJointParameters {
        position -1.1988835092680006e-05
        anchor -0.2987 -0.06 0
      }
      device [
        RotationalMotor {
          name "RR_hip_joint"
          maxVelocity 22
          minPosition -0.741764919444444
          maxPosition 0.741764919444444
          maxTorque 150
        }
        PositionSensor {
          name "RR_hip_joint_sensor"
        }
      ]
      endPoint Solid {
        translation -0.2987 -0.06 0
        rotation -1 0 0 1.1988833859206752e-05
        children [
          Transform {
            scale 1 -1 1
            children [
              Shape {
                appearance DEF RR_hip_material PBRAppearance {
                  baseColor 0.8 1 0.8
                  roughness 1
                  metalness 0
                }
                geometry DEF RL_HIP_cw Mesh {
                  url [
                    "../protos/meshes/RL_HIP.STL"
                  ]
                  ccw FALSE
                }
              }
            ]
          }
          HingeJoint {
            jointParameters HingeJointParameters {
              position 0.8400014164989072
              axis 0 1 0
              anchor 0 -0.1341 0
            }
            device [
              RotationalMotor {
                name "RR_thigh_joint"
                maxVelocity 22
                minPosition -1.22173
                maxPosition 3.8397
                maxTorque 150
              }
              PositionSensor {
                name "RR_thigh_joint_sensor"
              }
            ]
            endPoint Solid {
              translation 0 -0.1341 0
              rotation 0 0.9999999999999999 0 0.8400014164989071
              children [
                Transform {
                  scale 1 -1 1
                  children [
                    Shape {
                      appearance DEF RR_thigh_material PBRAppearance {
                        baseColor 1 0.5 1
                        roughness 1
                        metalness 0
                      }
                      geometry USE FL_THIGH_cw
                    }
                  ]
                }
                HingeJoint {
                  jointParameters HingeJointParameters {
                    position -1.6100207490346292
                    axis 0 1 0
                    anchor 0 0 -0.26
                  }
                  device [
                    RotationalMotor {
                      name "RR_calf_joint"
                      maxVelocity 22
                      minPosition -2.77507346333333
                      maxPosition -0.541052058888889
                      maxTorque 150
                    }
                    PositionSensor {
                      name "RR_calf_joint_sensor"
                    }
                  ]
                  endPoint Solid {
                    translation 0 0 -0.26
                    rotation 0 -1 0 1.6100207490346292
                    children [
                      Transform {
                        scale 1 -1 1
                        children [
                          Shape {
                            appearance DEF RR_calf_material PBRAppearance {
                              baseColor 1 0.4 0.4
                              roughness 1
                              metalness 0
                            }
                            geometry USE FL_CALF_cw
                          }
                        ]
                      }
                      Solid {
                        translation 0 0 -0.26149
                        children [
                          Shape {
                            appearance DEF RR_foot_material PBRAppearance {
                              baseColor 1 1 0.4
                              roughness 1
                              metalness 0
                            }
                            geometry Sphere {
                              radius 0.026
                            }
                          }
                        ]
                        name "RR_foot"
                        boundingObject Sphere {
                          radius 0.026
                        }
                        physics Physics {
                          density -1
                          mass 0.000205
                          centerOfMass [
                            0 0 0
                          ]
                          inertiaMatrix [
                            1.096001e-09 1.096001e-09 1.096001e-09
                            0 0 0
                          ]
                        }
                      }
                    ]
                    name "RR_calf"
                    boundingObject Group {
                      children [
                        Pose {
                          translation 0.00919 0 -0.06536
                          rotation 0 -1 0 0.139626
                          children [
                            Box {
                              size 0.033 0.033 0.23
                            }
                          ]
                        }
                        Pose {
                          translation 0.01381 0 -0.21574
                          rotation 0 1 0 0.24103
                          children [
                            Box {
                              size 0.036 0.036 0.09273
                            }
                          ]
                        }
                      ]
                    }
                    physics Physics {
                      density -1
                      mass 0.302786
                      centerOfMass [
                        0.008 -0.003625 -0.128915
                      ]
                      inertiaMatrix [
                        0.0085187 0.0085725 0.0001128
                        -8.6e-06 0.0003718 -0.0001434
                      ]
                    }
                  }
                }
              ]
              name "RR_thigh"
              boundingObject Group {
                children [
                  Pose {
                    translation 0 0.02125 0
                    rotation 0.5775032287046065 0.5775032287046065 -0.5770442285228318 2.093475
                    children [
                      Cylinder {
                        height 0.085
                        radius 0.058
                      }
                    ]
                  }
                  Pose {
                    translation -0.02158 0 -0.09691
                    rotation 0 1 0 0.122173
                    children [
                      Box {
                        size 0.06368 0.036 0.19764
                      }
                    ]
                  }
                  Pose {
                    translation -0.01645 0 -0.23181
                    rotation 0 -1 0 0.436332
                    children [
                      Box {
                        size 0.054 0.036 0.115
                      }
                    ]
                  }
                ]
              }
              physics Physics {
                density -1
                mass 2.930464
                centerOfMass [
                  -0.003481 0.032125 -0.031894
                ]
                inertiaMatrix [
                  0.0264127 0.0232267 0.0081071
                  -5.18e-05 0.0012845 -0.0002853
                ]
              }
            }
          }
        ]
        name "RR_hip"
        physics Physics {
          density -1
          mass 1.87369
          centerOfMass [
            -0.002155 -0.006319 1e-06
          ]
          inertiaMatrix [
            0.0021359 0.0034595 0.002322
            -2.5e-05 0 0
          ]
        }
      }
    }
    Solid {
      translation 0.17 0 0.08
      children [
        Shape {
          appearance DEF link0_material PBRAppearance {
            baseColor 0.75294 0.75294 0.75294
            roughness 1
            metalness 0
          }
          geometry DEF link0 Mesh {
            url [
              "../protos/meshes/link0.STL"
            ]
          }
        }
        HingeJoint {
          jointParameters HingeJointParameters {
            position 2.604541194172087e-07
            axis 0 0 1
            anchor 0 0 0.0605
          }
          device [
            RotationalMotor {
              name "joint1"
              maxVelocity 1000
              minPosition -3.14
              maxPosition 2.6
              maxTorque 100
            }
            PositionSensor {
              name "joint1_sensor"
            }
          ]
          endPoint Solid {
            translation 0 0 0.0605
            rotation 0 0 1 2.598106231415675e-07
            children [
              Shape {
                appearance DEF link1_material PBRAppearance {
                  baseColor 0.79216 0.81961 0.93333
                  roughness 1
                  metalness 0
                }
                geometry DEF link1 Mesh {
                  url [
                    "../protos/meshes/link1.STL"
                  ]
                }
              }
              HingeJoint {
                jointParameters HingeJointParameters {
                  position -7.446178376113721e-07
                  axis 0 1 0
                  anchor 0.02 0 0.04
                }
                device [
                  RotationalMotor {
                    name "joint2"
                    maxVelocity 1000
                    minPosition -0.1
                    maxPosition 3.6
                    maxTorque 100
                  }
                  PositionSensor {
                    name "joint2_sensor"
                  }
                ]
                endPoint Solid {
                  translation 0.02 0 0.04
                  rotation 0 -1 0 7.444617746351282e-07
                  children [
                    Shape {
                      appearance DEF link2_material PBRAppearance {
                        baseColor 0.75294 0.75294 0.75294
                        roughness 1
                        metalness 0
                      }
                      geometry DEF link2 Mesh {
                        url [
                          "../protos/meshes/link2.STL"
                        ]
                      }
                    }
                    HingeJoint {
                      jointParameters HingeJointParameters {
                        position -5.494592543620058e-06
                        axis 0 -1 -7e-06
                        anchor -0.264 0 0
                      }
                      device [
                        RotationalMotor {
                          name "joint3"
                          maxVelocity 1000
                          minPosition -5.494592543620058e-06
                          maxPosition 3.14
                          maxTorque 100
                        }
                        PositionSensor {
                          name "joint3_sensor"
                        }
                      ]
                      endPoint Solid {
                        translation -0.264 0 0
                        rotation 0.9999999999962262 9.13969121634909e-12 -2.747296271809904e-06 3.1416
                        children [
                          Shape {
                            appearance DEF link3_material PBRAppearance {
                              baseColor 1 0.98431 0.96471
                              roughness 1
                              metalness 0
                            }
                            geometry DEF link3 Mesh {
                              url [
                                "../protos/meshes/link3.STL"
                              ]
                            }
                          }
                          HingeJoint {
                            jointParameters HingeJointParameters {
                              position -1.3223568213760473e-06
                              axis 0 1 0
                              anchor 0.245 0 -0.056
                            }
                            device [
                              RotationalMotor {
                                name "joint4"
                                maxVelocity 1000
                                minPosition -1.3
                                maxPosition 1.3
                                maxTorque 100
                              }
                              PositionSensor {
                                name "joint4_sensor"
                              }
                            ]
                            endPoint Solid {
                              translation 0.245 0 -0.056
                              rotation 0 -0.9999999999999999 0 1.3224308331211922e-06
                              children [
                                Shape {
                                  appearance DEF link4_material PBRAppearance {
                                    baseColor 0.79216 0.81961 0.92941
                                    roughness 1
                                    metalness 0
                                  }
                                  geometry DEF link4 Mesh {
                                    url [
                                      "../protos/meshes/link4.STL"
                                    ]
                                  }
                                }
                                HingeJoint {
                                  jointParameters HingeJointParameters {
                                    position 7.680723128117333e-07
                                    axis 0 0 1
                                    anchor 0.06775 0.0005 -0.0865
                                  }
                                  device [
                                    RotationalMotor {
                                      name "joint5"
                                      maxVelocity 1000
                                      minPosition -1.57
                                      maxPosition 1.57
                                      maxTorque 100
                                    }
                                    PositionSensor {
                                      name "joint5_sensor"
                                    }
                                  ]
                                  endPoint Solid {
                                    translation 0.06775 0.0005 -0.0865
                                    rotation 0 0 0.9999999999999999 7.679521278575185e-07
                                    children [
                                      Shape {
                                        appearance DEF link5_material PBRAppearance {
                                          baseColor 0.69804 0.69804 0.69804
                                          roughness 1
                                          metalness 0
                                        }
                                        geometry DEF link5 Mesh {
                                          url [
                                            "../protos/meshes/link5.STL"
                                          ]
                                        }
                                      }
                                      HingeJoint {
                                        jointParameters HingeJointParameters {
                                          position 4.7094022778392543e-07
                                          anchor 0.02895 0 0.0865
                                        }
                                        device [
                                          RotationalMotor {
                                            name "joint6"
                                            maxVelocity 1000
                                            minPosition -2.1
                                            maxPosition 2.1
                                            maxTorque 100
                                          }
                                          PositionSensor {
                                            name "joint6_sensor"
                                          }
                                        ]
                                        endPoint Solid {
                                          translation 0.02895 0 0.0865
                                          rotation -1 0 0 3.1415995290597722
                                          children [
                                            Shape {
                                              appearance DEF link6_material PBRAppearance {
                                                baseColor 0.89804 0.91765 0.92941
                                                roughness 1
                                                metalness 0
                                              }
                                              geometry DEF link6 Mesh {
                                                url [
                                                  "../protos/meshes/link6.STL"
                                                ]
                                              }
                                            }
                                            SliderJoint {
                                              jointParameters JointParameters {
                                                position -4.5464458567780565e-10
                                                axis 0 1 0
                                              }
                                              device [
                                                LinearMotor {
                                                  name "joint7"
                                                  maxVelocity 1000
                                                  minPosition -4.5464458567780565e-10
                                                  maxPosition 0.044
                                                  maxForce 100
                                                }
                                                PositionSensor {
                                                  name "joint7_sensor"
                                                }
                                              ]
                                              endPoint Solid {
                                                translation 0.08657 0.024895999545355416 -0.000244
                                                children [
                                                  Shape {
                                                    appearance DEF link7_material PBRAppearance {
                                                      roughness 1
                                                      metalness 0
                                                    }
                                                    geometry DEF link7 Mesh {
                                                      url [
                                                        "../protos/meshes/link7.STL"
                                                      ]
                                                    }
                                                  }
                                                ]
                                                name "link7"
                                                boundingObject Group {
                                                  children [
                                                    Pose {
                                                      translation 0.05 -0.023 0
                                                      children [
                                                        Box {
                                                          size 0.04 0.004 0.0105
                                                        }
                                                      ]
                                                    }
                                                    Pose {
                                                      translation 0.015 -0.023 0
                                                      children [
                                                        Box {
                                                          size 0.03 0.004 0.036
                                                        }
                                                      ]
                                                    }
                                                  ]
                                                }
                                                physics Physics {
                                                  density -1
                                                  mass 0.064798
                                                  centerOfMass [
                                                    -0.000355 -0.007827 -0.002988
                                                  ]
                                                  inertiaMatrix [
                                                    2e-05 3e-05 3e-05
                                                    0 0 0
                                                  ]
                                                }
                                              }
                                            }
                                            SliderJoint {
                                              jointParameters JointParameters {
                                                position 4.5472714288588713e-10
                                                axis 0 -1 0
                                              }
                                              device [
                                                LinearMotor {
                                                  name "joint8"
                                                  maxVelocity 1000
                                                  maxPosition 0.044
                                                  maxForce 100
                                                }
                                                PositionSensor {
                                                  name "joint8_sensor"
                                                }
                                              ]
                                              endPoint Solid {
                                                translation 0.08657 -0.02490000045472714 -0.000244
                                                children [
                                                  Shape {
                                                    appearance DEF link8_material PBRAppearance {
                                                      roughness 1
                                                      metalness 0
                                                    }
                                                    geometry DEF link8 Mesh {
                                                      url [
                                                        "../protos/meshes/link8.STL"
                                                      ]
                                                    }
                                                  }
                                                ]
                                                name "link8"
                                                boundingObject Group {
                                                  children [
                                                    Pose {
                                                      translation 0.05 0.023 0
                                                      children [
                                                        Box {
                                                          size 0.04 0.004 0.0105
                                                        }
                                                      ]
                                                    }
                                                    Pose {
                                                      translation 0.015 0.023 0
                                                      children [
                                                        Box {
                                                          size 0.03 0.004 0.036
                                                        }
                                                      ]
                                                    }
                                                  ]
                                                }
                                                physics Physics {
                                                  density -1
                                                  mass 0.064798
                                                  centerOfMass [
                                                    -0.000355 0.007828 0.00242
                                                  ]
                                                  inertiaMatrix [
                                                    2e-05 3e-05 3e-05
                                                    0 0 0
                                                  ]
                                                }
                                              }
                                            }
                                          ]
                                          name "link6"
                                          boundingObject Pose {
                                            translation 0.03 0 0
                                            rotation 0 1 0 1.57
                                            children [
                                              Cylinder {
                                                height 0.06
                                                radius 0.03
                                              }
                                            ]
                                          }
                                          physics Physics {
                                            density -1
                                            mass 0.44089
                                            centerOfMass [
                                              0.041697 2.4e-05 0.000145
                                            ]
                                            inertiaMatrix [
                                              0.00038 0.00028 0.0005
                                              0 0 0
                                            ]
                                          }
                                        }
                                      }
                                    ]
                                    name "link5"
                                    boundingObject Pose {
                                      translation 0.005 0 0.086
                                      rotation 0 1 0 1.57
                                      children [
                                        Cylinder {
                                          height 0.04
                                          radius 0.03
                                        }
                                      ]
                                    }
                                    physics Physics {
                                      density -1
                                      mass 0.63488
                                      centerOfMass [
                                        0.003612 -1.5e-05 0.055214
                                      ]
                                      inertiaMatrix [
                                        0.00083 0.00082 0.00026
                                        0 7e-05 0
                                      ]
                                    }
                                  }
                                }
                              ]
                              name "link4"
                              boundingObject Pose {
                                translation 0.068 0 -0.066
                                children [
                                  Cylinder {
                                    height 0.04
                                    radius 0.03
                                  }
                                ]
                              }
                              physics Physics {
                                density -1
                                mass 0.11714
                                centerOfMass [
                                  0.040231 0.004481 -0.035335
                                ]
                                inertiaMatrix [
                                  0.00019 0.00023 0.00014
                                  -2e-05 -9e-05 2e-05
                                ]
                              }
                            }
                          }
                        ]
                        name "link3"
                        boundingObject Group {
                          children [
                            Pose {
                              translation 0.245 0 -0.056
                              rotation 1 0 0 1.57
                              children [
                                Cylinder {
                                  height 0.05
                                  radius 0.028
                                }
                              ]
                            }
                            Pose {
                              translation 0.135 0 -0.056
                              children [
                                Box {
                                  size 0.19 0.05 0.04
                                }
                              ]
                            }
                          ]
                        }
                        physics Physics {
                          density -1
                          mass 0.54534
                          centerOfMass [
                            0.18531 0.000684 -0.051638
                          ]
                          inertiaMatrix [
                            0.00036 0.00423 0.0042
                            -3e-05 -0.00039 1e-05
                          ]
                        }
                      }
                    }
                  ]
                  name "link2"
                  boundingObject Group {
                    children [
                      Pose {
                        rotation 1 0 0 1.57
                        children [
                          Cylinder {
                            height 0.06
                            radius 0.03
                          }
                        ]
                      }
                      Pose {
                        translation -0.13 0 0
                        children [
                          Box {
                            size 0.22 0.06 0.05
                          }
                        ]
                      }
                      Pose {
                        translation -0.26 0 0
                        rotation 1 0 0 1.57
                        children [
                          Cylinder {
                            height 0.06
                            radius 0.03
                          }
                        ]
                      }
                    ]
                  }
                  physics Physics {
                    density -1
                    mass 1.0795
                    centerOfMass [
                      -0.13237 0.002085 0.000105
                    ]
                    inertiaMatrix [
                      0.00051 0.01599 0.01605
                      1e-05 -4e-05 0
                    ]
                  }
                }
              }
            ]
            name "link1"
            physics Physics {
              density -1
              mass 0.066982
              centerOfMass [
                0.005423 -0.008029 0.017086
              ]
              inertiaMatrix [
                8e-05 3e-05 8e-05
                0 1e-05 0
              ]
            }
          }
        }
      ]
      name "link0"
      boundingObject Pose {
        translation 0 0 0.03
        children [
          Cylinder {
            height 0.06
            radius 0.03
          }
        ]
      }
      physics Physics {
        density -1
        mass 0.43995
        centerOfMass [
          -3e-05 3.1e-05 0.027324
        ]
        inertiaMatrix [
          0.00017 0.00017 0.00016
          0 0 0
        ]
      }
    }
  ]
  name "Grq20V2d3Default"
  boundingObject Group {
    children [
      Pose {
        translation 0 0 -0.01
        children [
          Box {
            size 0.42 0.26 0.18
          }
        ]
      }
      Pose {
        translation 0.32 0 0.01
        children [
          Box {
            size 0.22 0.16 0.14
          }
        ]
      }
      Pose {
        translation -0.32 0 0.01
        children [
          Box {
            size 0.22 0.16 0.14
          }
        ]
      }
      Pose {
        translation 0.27 0 0.1
        children [
          Box {
            size 0.06 0.16 0.05
          }
        ]
      }
      Pose {
        translation -0.27 0 0.1
        children [
          Box {
            size 0.06 0.16 0.05
          }
        ]
      }
    ]
  }
  physics Physics {
    density -1
    mass 25.267696
    centerOfMass [
      -0.001678 -0.004565 0.003165
    ]
    inertiaMatrix [
      0.166907 0.8444934 0.9116615
      -0.0002328 0.0044427 -0.0002798
    ]
  }
  supervisor TRUE
}
